Workbook

Sheet บันทึกสต็อครายวัน
A1: 📋 กรอกข้อมูลรายวัน | F1: 46186 | I1: SND
A2: YC STOCK — บันทึกสต็อครายวัน
A3: วันที่ (auto) | B3: สาขา (auto) | C3: ชีต | D3: หมวด | E3: รายการ | F3: หน่วยบรรจุ | G3: ยกมา (แพ็ค/กล่อง) | H3: ยกมา (ชิ้น/กรัม) | I3: รับเข้า (แพ็ค/กล่อง) | J3: รับเข้า (ชิ้น/กรัม) | K3: ขายไป / ใช้ไป | L3: คงเหลือ (แพ็ค/กล่อง) | M3: คงเหลือ (ชิ้น/กรัม) | N3: ส่งคืน | O3: หมายเหตุ | P3: ผลต่าง / ปริมาณใช้ | Q3: Par Level (สต็อคขั้นต่ำ) | R3: สถานะสต็อค
A4: 46186 | B4: SND | C4: #1 | D4: Yogurt 1kg/Box | E4: Greek Yogurt 1kg | F4: 1kg/Box | G4: 2 | H4: 542 | I4: 4 | J4: 0 | K4: 0 | L4: 6 | M4: 540 | N4: 0 | O4: 0 | P4: 0 | R4: ✓ ปกติ
A5: 46186 | B5: SND | C5: #1 | D5: Yogurt 1kg/Box | E5: Yuzu | F5: 1kg/Box | G5: 1 | H5: 340 | I5: 0 | J5: 0 | K5: 0 | L5: 1 | M5: 340 | N5: 0 | O5: 0 | P5: 0
A6: 46186 | B6: SND | C6: #1 | D6: Yogurt 1kg/Box | E6: Kyoho | F6: 1kg/Box | G6: 1 | H6: 330 | I6: 0 | J6: 0 | K6: 0 | L6: 1 | M6: 330 | N6: 0 | O6: 0 | P6: 0
A7: 46186 | B7: SND | C7: #1 | D7: Yogurt 1kg/Box | E7: Mint | F7: 1kg/Box | G7: 0 | H7: 0 | I7: 0 | J7: 0 | K7: 0 | L7: 0 | M7: 0 | N7: 0 | O7: 0 | P7: 0
A8: 46186 | B8: SND | C8: #1 | D8: Yogurt 1kg/Box | E8: Vanilla | F8: 1kg/Box | G8: 1 | H8: 0 | I8: 0 | J8: 0 | K8: 0 | L8: 1 | M8: 0 | N8: 0 | O8: 0 | P8: 0
A9: 46186 | B9: SND | C9: #1 | D9: Yogurt 1kg/Box | E9: Pineapple | F9: 1kg/Box | G9: 1 | H9: 500 | I9: 0 | J9: 0 | K9: 0 | L9: 1 | M9: 500 | N9: 0 | O9: 0 | P9: 0
A10: 46186 | B10: SND | C10: #1 | D10: Yogurt 1kg/Box | E10: Biscoff | F10: 1kg/Box | G10: 0 | H10: 599 | I10: 1 | J10: 350 | K10: 0 | L10: 1 | M10: 499 | N10: 0 | O10: 0 | P10: 0
A11: 46186 | B11: SND | C11: #1 | D11: Yogurt 1kg/Box | E11: Overnight oats biscoff | F11: 1kg/Box | G11: 2 | H11: 303 | I11: 0 | J11: 0 | K11: 0 | L11: 2 | M11: 300 | N11: 0 | O11: 0 | P11: 0
A12: 46186 | B12: SND | C12: #1 | D12: Yogurt 1kg/Box | E12: Plain Yogurt (ธรรมชาติ) | F12: 1kg/Box | G12: 5 | H12: 863 | I12: 2 | J12: 0 | K12: 0 | L12: 7 | M12: 683 | N12: 0 | O12: 0 | P12: 0
A13: 46186 | B13: SND | C13: #1 | D13: Yogurt 500g/Box | E13: Greek Yogurt 500g | F13: 500g/Box | G13: 6 | H13: 0 | I13: 5 | J13: 0 | N13: 0 | O13: 0 | P13: 11
A14: 46186 | B14: SND | C14: #1 | D14: Yogurt 500g/Box | E14: Plain Yogurt 500g | F14: 500g/Box | G14: 4 | H14: 0 | I14: 0 | J14: 0 | N14: 0 | O14: 0 | P14: 4
A15: 46186 | B15: SND | C15: #1 | D15: ACAI | E15: R-ACAI Bowl | F15: Bowl | G15: 15 | H15: 0 | I15: 0 | J15: 0 | K15: 0 | L15: 15 | M15: 0 | N15: 0 | O15: 0 | P15: 0
A16: 46186 | B16: SND | C16: #1 | D16: ACAI | E16: S-ACAI Cup (mini) | F16: Cup | G16: 13 | H16: 0 | I16: 0 | J16: 0 | K16: 0 | L16: 13 | M16: 0 | N16: 0 | O16: 0 | P16: 0
A17: 46186 | B17: SND | C17: #1 | D17: Soft Serve / Ice Cream | E17: น้ำ Ice cream / Soft Serve | F17: 2kg/Bag
A18: 46186 | B18: SND | C18: #1 | D18: Soft Serve / Ice Cream | E18: Granola โรย Ice cream | F18: g.
A19: 46186 | B19: SND | C19: #1 | D19: Softserve TH | E19: Softserve ถ้วยกระดาษ | F19: ถ้วย | G19: 0 | H19: 0 | I19: 0 | J19: 0 | K19: 0 | L19: 0 | M19: 0 | N19: 0 | O19: 0 | P19: 0
A20: 46186 | B20: SND | C20: #1 | D20: Shake แข็ง | E20: Shake (แช่แข็ง) | F20: ถ้วย | G20: 37 | H20: 0 | I20: 50 | J20: 0 | K20: 3 | L20: 84 | M20: 0 | N20: 0 | O20: 0
A21: 46186 | B21: SND | C21: #1 | D21: Drink / แยมกระปุก | E21: Peanut Butter | F21: กระปุก
A22: 46186 | B22: SND | C22: #1 | D22: Drink / แยมกระปุก | E22: Water น้ำดื่ม | F22: ขวด | G22: 9 | H22: 0 | I22: 0 | J22: 0 | K22: 0 | L22: 9 | M22: 0 | N22: 0 | O22: 0
A23: 46186 | B23: SND | C23: #1 | D23: Drink / แยมกระปุก | E23: ถุงสตรอเบอรี่ | F23: ถุง | G23: 4 | H23: 0 | I23: 5 | J23: 0 | K23: 0 | L23: 9 | M23: 0 | N23: 0 | O23: 0
A24: 46186 | B24: SND | C24: #1 | D24: Drink / แยมกระปุก | E24: ถุงบลูเบอรี่ | F24: ถุง | G24: 1 | H24: 0 | I24: 5 | J24: 0 | K24: 0 | L24: 6 | M24: 0 | N24: 0 | O24: 0
A25: 46186 | B25: SND | C25: #1 | D25: Drink / แยมกระปุก | E25: ถุงธรรมชาติ | F25: ถุง | G25: 0 | H25: 0 | I25: 10 | J25: 0 | K25: 0 | L25: 10 | M25: 0 | N25: 0 | O25: 0
A26: 46186 | B26: SND | C26: #1 | D26: Drink / แยมกระปุก | E26: ถุงลิ้นจี่ | F26: ถุง | G26: 2 | H26: 0 | I26: 5 | J26: 0 | K26: 0 | L26: 7 | M26: 0 | N26: 0 | O26: 0
A27: 46186 | B27: SND | C27: #1 | D27: Drink / แยมกระปุก | E27: ถุงยูส | F27: ถุง | G27: 1 | H27: 0 | I27: 5 | J27: 0 | K27: 0 | L27: 6 | M27: 0 | N27: 0 | O27: 0
A28: 46186 | B28: SND | C28: #1 | D28: Drink / แยมกระปุก | E28: ถุงพีช | F28: ถุง | G28: 4 | H28: 0 | I28: 0 | J28: 0 | K28: 0 | L28: 4 | M28: 0 | N28: 0 | O28: 0
A29: 46186 | B29: SND | C29: #1 | D29: Cereals | E29: Cornflakes Malt (M) | F29: กระปุก | G29: 5 | H29: 0 | I29: 0 | J29: 0 | K29: 0 | L29: 5 | M29: 0 | N29: 0 | O29: 0 | P29: 0
A30: 46186 | B30: SND | C30: #1 | D30: Cereals | E30: Granola (M) | F30: กระปุก | G30: 5 | H30: 0 | I30: 0 | J30: 0 | K30: 0 | L30: 5 | M30: 0 | N30: 0 | O30: 0 | P30: 0
A31: 46186 | B31: SND | C31: #1 | D31: Cereals | E31: Choc Chip Cookies | F31: กระปุก | G31: 0 | H31: 0 | I31: 4 | J31: 0 | K31: 0 | L31: 4 | M31: 0 | N31: 0 | O31: 0 | P31: 0
A32: 46186 | B32: SND | C32: #2 | D32: Toppings | E32: Cookies Crumbs | F32: 750g/pack | G32: 2 | H32: 134 | I32: 0 | J32: 0 | K32: 0 | L32: 2 | M32: 74 | N32: 0 | O32: 0 | P32: 0
A33: 46186 | B33: SND | C33: #2 | D33: Toppings | E33: Oreo | F33: 454g/pack | G33: 2 | H33: 262 | I33: 0 | J33: 0 | K33: 0 | L33: 2 | M33: 260 | N33: 0 | O33: 0 | P33: 0
A34: 46186 | B34: SND | C34: #2 | D34: Toppings | E34: Choc Chips | F34: 300g/pack | G34: 0 | H34: 212 | I34: 1 | J34: 0 | K34: 0 | L34: 1 | M34: 210 | N34: 0 | O34: 0 | P34: 0
A35: 46186 | B35: SND | C35: #2 | D35: Toppings | E35: Cornflakes (Topping) | F35: 1,000g/box | G35: 0 | H35: 890 | I35: 0 | J35: 0 | K35: 0 | L35: 0 | M35: 890 | N35: 0 | O35: 0 | P35: 0
A36: 46186 | B36: SND | C36: #2 | D36: Toppings | E36: Granola (Topping) | F36: 2,000g/box | G36: 1 | H36: 158 | I36: 0 | J36: 0 | K36: 0 | L36: 1 | M36: 158 | N36: 0 | O36: 0 | P36: 0
A37: 46186 | B37: SND | C37: #2 | D37: Toppings | E37: Almond | F37: 400g/pack | G37: 1 | H37: 369 | I37: 0 | J37: 0 | K37: 0 | L37: 1 | M37: 369 | N37: 0 | O37: 0 | P37: 0
A38: 46186 | B38: SND | C38: #2 | D38: Toppings | E38: Pecan | F38: 400g/pack | G38: 1 | H38: 342 | I38: 0 | J38: 0 | K38: 0 | L38: 1 | M38: 342 | N38: 0 | O38: 0 | P38: 0
A39: 46186 | B39: SND | C39: #2 | D39: Toppings | E39: Walnut | F39: 400g/pack | G39: 1 | H39: 391 | I39: 0 | J39: 0 | K39: 0 | L39: 1 | M39: 391 | N39: 0 | O39: 0 | P39: 0
A40: 46186 | B40: SND | C40: #2 | D40: Toppings | E40: Coconut Chips | F40: 130g/box | G40: 0 | H40: 150 | I40: 0 | J40: 0 | K40: 0 | L40: 0 | M40: 150 | N40: 0 | O40: 0 | P40: 0
...

Sheet 📝 กรอกข้อมูล
A1: 📝 กรอกข้อมูลสต็อครายวัน | เปลี่ยน B2=วันที่ / E2=สาขา แล้วข้อมูลเปลี่ยนตาม | กรอกข้อมูลใหม่: พิมพ์ทับช่องสีได้เลย | พอครบบอก Claude: 'บันทึก [DD/MM] [สาขา]'
A2: วันที่: | B2: 46217 | D2: สาขา: | E2: SND
A3: หมวด | B3: รายการ | C3: หน่วย | D3: ยกมา (แพ็ค) | E3: ยกมา (ชิ้น/g) | F3: รับเข้า (แพ็ค) | G3: รับเข้า (ชิ้น/g) | H3: ขายไป /ใช้ไป | I3: คงเหลือ (แพ็ค) | J3: คงเหลือ (ชิ้น/g) | K3: ส่งคืน | L3: หมายเหตุ
A4: Yogurt 1kg/Box | B4: Greek Yogurt 1kg | C4: 1kg/Box | D4: =IFERROR(IF(INDEX(บันทึกสต็อครายวัน!$D$122:$D$9999,MATCH(TEXT($B$2,"YYYYMMDD")&"|"&$E$2&"|"&B4,บันทึกสต็อครายวัน!$M$122:$M$9999,0))="",IFERROR(IF(SUMPRODUCT(MAX((บันทึกสต็อครายวัน!$A$122:$A$9999<$B$2)*(บันทึกสต็อครายวัน!$B$122:$B$9999=$E$2)*(บันทึกสต็อครายวัน!$C$122:$C$9999=B4)*บันทึกสต็อครายวัน!$A$122:$A$9999))=0,"",INDEX(บันทึกสต็อครายวัน!$I$122:$I$9999,MATCH(TEXT(SUMPRODUCT(MAX((บันทึกสต็อครายวัน!$A$122:$A$9999<$B$2)*(บันทึกสต็อครายวัน!$B$122:$B$9999=$E$2)*(บันทึกสต็อครายวัน!$C$122:$C$9999=B4)*บันทึกสต็อครายวัน!$A$122:$A$9999)),"YYYYMMDD")&"|"&$E$2&"|"&B4,บันทึกสต็อครายวัน!$M$122:$M$9999,0))),""),INDEX(บันทึกสต็อครายวัน!$D$122:$D$9999,MATCH(TEXT($B$2,"YYYYMMDD")&"|"&$E$2&"|"&B4,บันทึกสต็อครายวัน!$M$122:$M$9999,0))),IFERROR(IF(SUMPRODUCT(MAX((บันทึกสต็อครายวัน!$A$122:$A$9999<$B$2)*(บันทึกสต็อครายวัน!$B$122:$B$9999=$E$2)*(บันทึกสต็อครายวัน!$C$122:$C$9999=B4)*บันทึกสต็อครายวัน!$A$122:$A$9999))=0,"",INDEX(บันทึกสต็อครายวัน!$I$122:$I$9999,MATCH(TEXT(SUMPRODUCT(MAX((บันทึกสต็อครายวัน!$A$122:$A$9999<$B$2)*(บันทึกสต็อครายวัน!$B$122:$B$9999=$E$2)*(บันทึกสต็อครายวัน!$C$122:$C$9999=B4)*บันทึกสต็อครายวัน!$A$122:$A$9999)),"YYYYMMDD")&"|"&$E$2&"|"&B4,บันทึกสต็อครายวัน!$M$122:$M$9999,0))),"")) -> 3 | E4: =IFERROR(IF(INDEX(บันทึกสต็อครายวัน!$E$122:$E$9999,MATCH(TEXT($B$2,"YYYYMMDD")&"|"&$E$2&"|"&B4,บันทึกสต็อครายวัน!$M$122:$M$9999,0))="",IFERROR(IF(SUMPRODUCT(MAX((บันทึกสต็อครายวัน!$A$122:$A$9999<$B$2)*(บันทึกสต็อครายวัน!$B$122:$B$9999=$E$2)*(บันทึกสต็อครายวัน!$C$122:$C$9999=B4)*บันทึกสต็อครายวัน!$A$122:$A$9999))=0,"",INDEX(บันทึกสต็อครายวัน!$J$122:$J$9999,MATCH(TEXT(SUMPRODUCT(MAX((บันทึกสต็อครายวัน!$A$122:$A$9999<$B$2)*(บันทึกสต็อครายวัน!$B$122:$B$9999=$E$2)*(บันทึกสต็อครายวัน!$C$122:$C$9999=B4)*บันทึกสต็อครายวัน!$A$122:$A$9999)),"YYYYMMDD")&"|"&$E$2&"|"&B4,บันทึกสต็อครายวัน!$M$122:$M$9999,0))),""),INDEX(บันทึกสต็อครายวัน!$E$122:$E$9999,MATCH(TEXT($B$2,"YYYYMMDD")&"|"&$E$2&"|"&B4,บันทึกสต็อครายวัน!$M$122:$M$9999,0))),IFERROR(IF(SUMPRODUCT(MAX((บันทึกสต็อครายวัน!$A$122:$A$9999<$B$2)*(บันทึกสต็อครายวัน!$B$122:$B$9999=$E$2)*(บันทึกสต็อครายวัน!$C$122:$C$9999=B4)*บันทึกสต็อครายวัน!$A$122:$A$9999))=0,"",INDEX(บันทึกสต็อครายวัน!$J$122:$J$9999,MATCH(TEXT(SUMPRODUCT(MAX((บันทึกสต็อครายวัน!$A$122:$A$9999<$B$2)*(บันทึกสต็อครายวัน!$B$122:$B$9999=$E$2)*(บันทึกสต็อครายวัน!$C$122:$C$9999=B4)*บันทึกสต็อครายวัน!$A$122:$A$9999)),"YYYYMMDD")&"|"&$E$2&"|"&B4,บันทึกสต็อครายวัน!$M$122:$M$9999,0))),"")) -> 750 | F4: =IFERROR(IF(ISBLANK(INDEX(บันทึกสต็อครายวัน!$F$122:$F$9999,MATCH(TEXT($B$2,"YYYYMMDD")&"|"&$E$2&"|"&B4,บันทึกสต็อครายวัน!$M$122:$M$9999,0))),"",INDEX(บันทึกสต็อครายวัน!$F$122:$F$9999,MATCH(TEXT($B$2,"YYYYMMDD")&"|"&$E$2&"|"&B4,บันทึกสต็อครายวัน!$M$122:$M$9999,0))),"") | G4: =IFERROR(IF(ISBLANK(INDEX(บันทึกสต็อครายวัน!$G$122:$G$9999,MATCH(TEXT($B$2,"YYYYMMDD")&"|"&$E$2&"|"&B4,บันทึกสต็อครายวัน!$M$122:$M$9999,0))),"",INDEX(บันทึกสต็อครายวัน!$G$122:$G$9999,MATCH(TEXT($B$2,"YYYYMMDD")&"|"&$E$2&"|"&B4,บันทึกสต็อครายวัน!$M$122:$M$9999,0))),"") | H4: =IFERROR(IF(ISBLANK(INDEX(บันทึกสต็อครายวัน!$H$122:$H$9999,MATCH(TEXT($B$2,"YYYYMMDD")&"|"&$E$2&"|"&B4,บันทึกสต็อครายวัน!$M$122:$M$9999,0))),"",INDEX(บันทึกสต็อครายวัน!$H$122:$H$9999,MATCH(TEXT($B$2,"YYYYMMDD")&"|"&$E$2&"|"&B4,บันทึกสต็อครายวัน!$M$122:$M$9999,0))),"") | I4: =IFERROR(IF(ISBLANK(INDEX(บันทึกสต็อครายวัน!$I$122:$I$9999,MATCH(TEXT($B$2,"YYYYMMDD")&"|"&$E$2&"|"&B4,บันทึกสต็อครายวัน!$M$122:$M$9999,0))),"",INDEX(บันทึกสต็อครายวัน!$I$122:$I$9999,MATCH(TEXT($B$2,"YYYYMMDD")&"|"&$E$2&"|"&B4,บันทึกสต็อครายวัน!$M$122:$M$9999,0))),"") | J4: =IFERROR(IF(ISBLANK(INDEX(บันทึกสต็อครายวัน!$J$122:$J$9999,MATCH(TEXT($B$2,"YYYYMMDD")&"|"&$E$2&"|"&B4,บันทึกสต็อครายวัน!$M$122:$M$9999,0))),"",INDEX(บันทึกสต็อครายวัน!$J$122:$J$9999,MATCH(TEXT($B$2,"YYYYMMDD")&"|"&$E$2&"|"&B4,บันทึกสต็อครายวัน!$M$122:$M$9999,0))),"") | K4: =IFERROR(IF(ISBLANK(INDEX(บันทึกสต็อครายวัน!$K$122:$K$9999,MATCH(TEXT($B$2,"YYYYMMDD")&"|"&$E$2&"|"&B4,บันทึกสต็อครายวัน!$M$122:$M$9999,0))),"",INDEX(บันทึกสต็อครายวัน!$K$122:$K$9999,MATCH(TEXT($B$2,"YYYYMMDD")&"|"&$E$2&"|"&B4,บันทึกสต็อครายวัน!$M$122:$M$9999,0))),"") | L4: =IFERROR(IF(ISBLANK(INDEX(บันทึกสต็อครายวัน!$L$122:$L$9999,MATCH(TEXT($B$2,"YYYYMMDD")&"|"&$E$2&"|"&B4,บันทึกสต็อครายวัน!$M$122:$M$9999,0))),"",INDEX(บันทึกสต็อครายวัน!$L$122:$L$9999,MATCH(TEXT($B$2,"YYYYMMDD")&"|"&$E$2&"|"&B4,บันทึกสต็อครายวัน!$M$122:$M$9999,0))),"")
A5: Yogurt 1kg/Box | B5: Yuzu | C5: 1kg/Box | D5: =IFERROR(IF(INDEX(บันทึกสต็อครายวัน!$D$122:$D$9999,MATCH(TEXT($B$2,"YYYYMMDD")&"|"&$E$2&"|"&B5,บันทึกสต็อครายวัน!$M$122:$M$9999,0))="",IFERROR(IF(SUMPRODUCT(MAX((บันทึกสต็อครายวัน!$A$122:$A$9999<$B$2)*(บันทึกสต็อครายวัน!$B$122:$B$9999=$E$2)*(บันทึกสต็อครายวัน!$C$122:$C$9999=B5)*บันทึกสต็อครายวัน!$A$122:$A$9999))=0,"",INDEX(บันทึกสต็อครายวัน!$I$122:$I$9999,MATCH(TEXT(SUMPRODUCT(MAX((บันทึกสต็อครายวัน!$A$122:$A$9999<$B$2)*(บันทึกสต็อครายวัน!$B$122:$B$9999=$E$2)*(บันทึกสต็อครายวัน!$C$122:$C$9999=B5)*บันทึกสต็อครายวัน!$A$122:$A$9999)),"YYYYMMDD")&"|"&$E$2&"|"&B5,บันทึกสต็อครายวัน!$M$122:$M$9999,0))),""),INDEX(บันทึกสต็อครายวัน!$D$122:$D$9999,MATCH(TEXT($B$2,"YYYYMMDD")&"|"&$E$2&"|"&B5,บันทึกสต็อครายวัน!$M$122:$M$9999,0))),IFERROR(IF(SUMPRODUCT(MAX((บันทึกสต็อครายวัน!$A$122:$A$9999<$B$2)*(บันทึกสต็อครายวัน!$B$122:$B$9999=$E$2)*(บันทึกสต็อครายวัน!$C$122:$C$9999=B5)*บันทึกสต็อครายวัน!$A$122:$A$9999))=0,"",INDEX(บันทึกสต็อครายวัน!$I$122:$I$9999,MATCH(TEXT(SUMPRODUCT(MAX((บันทึกสต็อครายวัน!$A$122:$A$9999<$B$2)*(บันทึกสต็อครายวัน!$B$122:$B$9999=$E$2)*(บันทึกสต็อครายวัน!$C$122:$C$9999=B5)*บันทึกสต็อครายวัน!$A$122:$A$9999)),"YYYYMMDD")&"|"&$E$2&"|"&B5,บันทึกสต็อครายวัน!$M$122:$M$9999,0))),"")) -> 1 | E5: =IFERROR(IF(INDEX(บันทึกสต็อครายวัน!$E$122:$E$9999,MATCH(TEXT($B$2,"YYYYMMDD")&"|"&$E$2&"|"&B5,บันทึกสต็อครายวัน!$M$122:$M$9999,0))="",IFERROR(IF(SUMPRODUCT(MAX((บันทึกสต็อครายวัน!$A$122:$A$9999<$B$2)*(บันทึกสต็อครายวัน!$B$122:$B$9999=$E$2)*(บันทึกสต็อครายวัน!$C$122:$C$9999=B5)*บันทึกสต็อครายวัน!$A$122:$A$9999))=0,"",INDEX(บันทึกสต็อครายวัน!$J$122:$J$9999,MATCH(TEXT(SUMPRODUCT(MAX((บันทึกสต็อครายวัน!$A$122:$A$9999<$B$2)*(บันทึกสต็อครายวัน!$B$122:$B$9999=$E$2)*(บันทึกสต็อครายวัน!$C$122:$C$9999=B5)*บันทึกสต็อครายวัน!$A$122:$A$9999)),"YYYYMMDD")&"|"&$E$2&"|"&B5,บันทึกสต็อครายวัน!$M$122:$M$9999,0))),""),INDEX(บันทึกสต็อครายวัน!$E$122:$E$9999,MATCH(TEXT($B$2,"YYYYMMDD")&"|"&$E$2&"|"&B5,บันทึกสต็อครายวัน!$M$122:$M$9999,0))),IFERROR(IF(SUMPRODUCT(MAX((บันทึกสต็อครายวัน!$A$122:$A$9999<$B$2)*(บันทึกสต็อครายวัน!$B$122:$B$9999=$E$2)*(บันทึกสต็อครายวัน!$C$122:$C$9999=B5)*บันทึกสต็อครายวัน!$A$122:$A$9999))=0,"",INDEX(บันทึกสต็อครายวัน!$J$122:$J$9999,MATCH(TEXT(SUMPRODUCT(MAX((บันทึกสต็อครายวัน!$A$122:$A$9999<$B$2)*(บันทึกสต็อครายวัน!$B$122:$B$9999=$E$2)*(บันทึกสต็อครายวัน!$C$122:$C$9999=B5)*บันทึกสต็อครายวัน!$A$122:$A$9999)),"YYYYMMDD")&"|"&$E$2&"|"&B5,บันทึกสต็อครายวัน!$M$122:$M$9999,0))),"")) -> 616 | F5: =IFERROR(IF(ISBLANK(INDEX(บันทึกสต็อครายวัน!$F$122:$F$9999,MATCH(TEXT($B$2,"YYYYMMDD")&"|"&$E$2&"|"&B5,บันทึกสต็อครายวัน!$M$122:$M$9999,0))),"",INDEX(บันทึกสต็อครายวัน!$F$122:$F$9999,MATCH(TEXT($B$2,"YYYYMMDD")&"|"&$E$2&"|"&B5,บันทึกสต็อครายวัน!$M$122:$M$9999,0))),"") | G5: =IFERROR(IF(ISBLANK(INDEX(บันทึกสต็อครายวัน!$G$122:$G$9999,MATCH(TEXT($B$2,"YYYYMMDD")&"|"&$E$2&"|"&B5,บันทึกสต็อครายวัน!$M$122:$M$9999,0))),"",INDEX(บันทึกสต็อครายวัน!$G$122:$G$9999,MATCH(TEXT($B$2,"YYYYMMDD")&"|"&$E$2&"|"&B5,บันทึกสต็อครายวัน!$M$122:$M$9999,0))),"") | H5: =IFERROR(IF(ISBLANK(INDEX(บันทึกสต็อครายวัน!$H$122:$H$9999,MATCH(TEXT($B$2,"YYYYMMDD")&"|"&$E$2&"|"&B5,บันทึกสต็อครายวัน!$M$122:$M$9999,0))),"",INDEX(บันทึกสต็อครายวัน!$H$122:$H$9999,MATCH(TEXT($B$2,"YYYYMMDD")&"|"&$E$2&"|"&B5,บันทึกสต็อครายวัน!$M$122:$M$9999,0))),"") | I5: =IFERROR(IF(ISBLANK(INDEX(บันทึกสต็อครายวัน!$I$122:$I$9999,MATCH(TEXT($B$2,"YYYYMMDD")&"|"&$E$2&"|"&B5,บันทึกสต็อครายวัน!$M$122:$M$9999,0))),"",INDEX(บันทึกสต็อครายวัน!$I$122:$I$9999,MATCH(TEXT($B$2,"YYYYMMDD")&"|"&$E$2&"|"&B5,บันทึกสต็อครายวัน!$M$122:$M$9999,0))),"") | J5: =IFERROR(IF(ISBLANK(INDEX(บันทึกสต็อครายวัน!$J$122:$J$9999,MATCH(TEXT($B$2,"YYYYMMDD")&"|"&$E$2&"|"&B5,บันทึกสต็อครายวัน!$M$122:$M$9999,0))),"",INDEX(บันทึกสต็อครายวัน!$J$122:$J$9999,MATCH(TEXT($B$2,"YYYYMMDD")&"|"&$E$2&"|"&B5,บันทึกสต็อครายวัน!$M$122:$M$9999,0))),"") | K5: =IFERROR(IF(ISBLANK(INDEX(บันทึกสต็อครายวัน!$K$122:$K$9999,MATCH(TEXT($B$2,"YYYYMMDD")&"|"&$E$2&"|"&B5,บันทึกสต็อครายวัน!$M$122:$M$9999,0))),"",INDEX(บันทึกสต็อครายวัน!$K$122:$K$9999,MATCH(TEXT($B$2,"YYYYMMDD")&"|"&$E$2&"|"&B5,บันทึกสต็อครายวัน!$M$122:$M$9999,0))),"") | L5: =IFERROR(IF(ISBLANK(INDEX(บันทึกสต็อครายวัน!$L$122:$L$9999,MATCH(TEXT($B$2,"YYYYMMDD")&"|"&$E$2&"|"&B5,บันทึกสต็อครายวัน!$M$122:$M$9999,0))),"",INDEX(บันทึกสต็อครายวัน!$L$122:$L$9999,MATCH(TEXT($B$2,"YYYYMMDD")&"|"&$E$2&"|"&B5,บันทึกสต็อครายวัน!$M$122:$M$9999,0))),"")
A6: Yogurt 1kg/Box | B6: Kyoho | C6: 1kg/Box | D6: =IFERROR(IF(INDEX(บันทึกสต็อครายวัน!$D$122:$D$9999,MATCH(TEXT($B$2,"YYYYMMDD")&"|"&$E$2&"|"&B6,บันทึกสต็อครายวัน!$M$122:$M$9999,0))="",IFERROR(IF(SUMPRODUCT(MAX((บันทึกสต็อครายวัน!$A$122:$A$9999<$B$2)*(บันทึกสต็อครายวัน!$B$122:$B$9999=$E$2)*(บันทึกสต็อครายวัน!$C$122:$C$9999=B6)*บันทึกสต็อครายวัน!$A$122:$A$9999))=0,"",INDEX(บันทึกสต็อครายวัน!$I$122:$I$9999,MATCH(TEXT(SUMPRODUCT(MAX((บันทึกสต็อครายวัน!$A$122:$A$9999<$B$2)*(บันทึกสต็อครายวัน!$B$122:$B$9999=$E$2)*(บันทึกสต็อครายวัน!$C$122:$C$9999=B6)*บันทึกสต็อครายวัน!$A$122:$A$9999)),"YYYYMMDD")&"|"&$E$2&"|"&B6,บันทึกสต็อครายวัน!$M$122:$M$9999,0))),""),INDEX(บันทึกสต็อครายวัน!$D$122:$D$9999,MATCH(TEXT($B$2,"YYYYMMDD")&"|"&$E$2&"|"&B6,บันทึกสต็อครายวัน!$M$122:$M$9999,0))),IFERROR(IF(SUMPRODUCT(MAX((บันทึกสต็อครายวัน!$A$122:$A$9999<$B$2)*(บันทึกสต็อครายวัน!$B$122:$B$9999=$E$2)*(บันทึกสต็อครายวัน!$C$122:$C$9999=B6)*บันทึกสต็อครายวัน!$A$122:$A$9999))=0,"",INDEX(บันทึกสต็อครายวัน!$I$122:$I$9999,MATCH(TEXT(SUMPRODUCT(MAX((บันทึกสต็อครายวัน!$A$122:$A$9999<$B$2)*(บันทึกสต็อครายวัน!$B$122:$B$9999=$E$2)*(บันทึกสต็อครายวัน!$C$122:$C$9999=B6)*บันทึกสต็อครายวัน!$A$122:$A$9999)),"YYYYMMDD")&"|"&$E$2&"|"&B6,บันทึกสต็อครายวัน!$M$122:$M$9999,0))),"")) -> 1 | E6: =IFERROR(IF(INDEX(บันทึกสต็อครายวัน!$E$122:$E$9999,MATCH(TEXT($B$2,"YYYYMMDD")&"|"&$E$2&"|"&B6,บันทึกสต็อครายวัน!$M$122:$M$9999,0))="",IFERROR(IF(SUMPRODUCT(MAX((บันทึกสต็อครายวัน!$A$122:$A$9999<$B$2)*(บันทึกสต็อครายวัน!$B$122:$B$9999=$E$2)*(บันทึกสต็อครายวัน!$C$122:$C$9999=B6)*บันทึกสต็อครายวัน!$A$122:$A$9999))=0,"",INDEX(บันทึกสต็อครายวัน!$J$122:$J$9999,MATCH(TEXT(SUMPRODUCT(MAX((บันทึกสต็อครายวัน!$A$122:$A$9999<$B$2)*(บันทึกสต็อครายวัน!$B$122:$B$9999=$E$2)*(บันทึกสต็อครายวัน!$C$122:$C$9999=B6)*บันทึกสต็อครายวัน!$A$122:$A$9999)),"YYYYMMDD")&"|"&$E$2&"|"&B6,บันทึกสต็อครายวัน!$M$122:$M$9999,0))),""),INDEX(บันทึกสต็อครายวัน!$E$122:$E$9999,MATCH(TEXT($B$2,"YYYYMMDD")&"|"&$E$2&"|"&B6,บันทึกสต็อครายวัน!$M$122:$M$9999,0))),IFERROR(IF(SUMPRODUCT(MAX((บันทึกสต็อครายวัน!$A$122:$A$9999<$B$2)*(บันทึกสต็อครายวัน!$B$122:$B$9999=$E$2)*(บันทึกสต็อครายวัน!$C$122:$C$9999=B6)*บันทึกสต็อครายวัน!$A$122:$A$9999))=0,"",INDEX(บันทึกสต็อครายวัน!$J$122:$J$9999,MATCH(TEXT(SUMPRODUCT(MAX((บันทึกสต็อครายวัน!$A$122:$A$9999<$B$2)*(บันทึกสต็อครายวัน!$B$122:$B$9999=$E$2)*(บันทึกสต็อครายวัน!$C$122:$C$9999=B6)*บันทึกสต็อครายวัน!$A$122:$A$9999)),"YYYYMMDD")&"|"&$E$2&"|"&B6,บันทึกสต็อครายวัน!$M$122:$M$9999,0))),"")) -> 1180 | F6: =IFERROR(IF(ISBLANK(INDEX(บันทึกสต็อครายวัน!$F$122:$F$9999,MATCH(TEXT($B$2,"YYYYMMDD")&"|"&$E$2&"|"&B6,บันทึกสต็อครายวัน!$M$122:$M$9999,0))),"",INDEX(บันทึกสต็อครายวัน!$F$122:$F$9999,MATCH(TEXT($B$2,"YYYYMMDD")&"|"&$E$2&"|"&B6,บันทึกสต็อครายวัน!$M$122:$M$9999,0))),"") | G6: =IFERROR(IF(ISBLANK(INDEX(บันทึกสต็อครายวัน!$G$122:$G$9999,MATCH(TEXT($B$2,"YYYYMMDD")&"|"&$E$2&"|"&B6,บันทึกสต็อครายวัน!$M$122:$M$9999,0))),"",INDEX(บันทึกสต็อครายวัน!$G$122:$G$9999,MATCH(TEXT($B$2,"YYYYMMDD")&"|"&$E$2&"|"&B6,บันทึกสต็อครายวัน!$M$122:$M$9999,0))),"") | H6: =IFERROR(IF(ISBLANK(INDEX(บันทึกสต็อครายวัน!$H$122:$H$9999,MATCH(TEXT($B$2,"YYYYMMDD")&"|"&$E$2&"|"&B6,บันทึกสต็อครายวัน!$M$122:$M$9999,0))),"",INDEX(บันทึกสต็อครายวัน!$H$122:$H$9999,MATCH(TEXT($B$2,"YYYYMMDD")&"|"&$E$2&"|"&B6,บันทึกสต็อครายวัน!$M$122:$M$9999,0))),"") | I6: =IFERROR(IF(ISBLANK(INDEX(บันทึกสต็อครายวัน!$I$122:$I$9999,MATCH(TEXT($B$2,"YYYYMMDD")&"|"&$E$2&"|"&B6,บันทึกสต็อครายวัน!$M$122:$M$9999,0))),"",INDEX(บันทึกสต็อครายวัน!$I$122:$I$9999,MATCH(TEXT($B$2,"YYYYMMDD")&"|"&$E$2&"|"&B6,บันทึกสต็อครายวัน!$M$122:$M$9999,0))),"") | J6: =IFERROR(IF(ISBLANK(INDEX(บันทึกสต็อครายวัน!$J$122:$J$9999,MATCH(TEXT($B$2,"YYYYMMDD")&"|"&$E$2&"|"&B6,บันทึกสต็อครายวัน!$M$122:$M$9999,0))),"",INDEX(บันทึกสต็อครายวัน!$J$122:$J$9999,MATCH(TEXT($B$2,"YYYYMMDD")&"|"&$E$2&"|"&B6,บันทึกสต็อครายวัน!$M$122:$M$9999,0))),"") | K6: =IFERROR(IF(ISBLANK(INDEX(บันทึกสต็อครายวัน!$K$122:$K$9999,MATCH(TEXT($B$2,"YYYYMMDD")&"|"&$E$2&"|"&B6,บันทึกสต็อครายวัน!$M$122:$M$9999,0))),"",INDEX(บันทึกสต็อครายวัน!$K$122:$K$9999,MATCH(TEXT($B$2,"YYYYMMDD")&"|"&$E$2&"|"&B6,บันทึกสต็อครายวัน!$M$122:$M$9999,0))),"") | L6: =IFERROR(IF(ISBLANK(INDEX(บันทึกสต็อครายวัน!$L$122:$L$9999,MATCH(TEXT($B$2,"YYYYMMDD")&"|"&$E$2&"|"&B6,บันทึกสต็อครายวัน!$M$122:$M$9999,0))),"",INDEX(บันทึกสต็อครายวัน!$L$122:$L$9999,MATCH(TEXT($B$2,"YYYYMMDD")&"|"&$E$2&"|"&B6,บันทึกสต็อครายวัน!$M$122:$M$9999,0))),"")
A7: Yogurt 1kg/Box | B7: Mint | C7: 1kg/Box | D7: =IFERROR(IF(INDEX(บันทึกสต็อครายวัน!$D$122:$D$9999,MATCH(TEXT($B$2,"YYYYMMDD")&"|"&$E$2&"|"&B7,บันทึกสต็อครายวัน!$M$122:$M$9999,0))="",IFERROR(IF(SUMPRODUCT(MAX((บันทึกสต็อครายวัน!$A$122:$A$9999<$B$2)*(บันทึกสต็อครายวัน!$B$122:$B$9999=$E$2)*(บันทึกสต็อครายวัน!$C$122:$C$9999=B7)*บันทึกสต็อครายวัน!$A$122:$A$9999))=0,"",INDEX(บันทึกสต็อครายวัน!$I$122:$I$9999,MATCH(TEXT(SUMPRODUCT(MAX((บันทึกสต็อครายวัน!$A$122:$A$9999<$B$2)*(บันทึกสต็อครายวัน!$B$122:$B$9999=$E$2)*(บันทึกสต็อครายวัน!$C$122:$C$9999=B7)*บันทึกสต็อครายวัน!$A$122:$A$9999)),"YYYYMMDD")&"|"&$E$2&"|"&B7,บันทึกสต็อครายวัน!$M$122:$M$9999,0))),""),INDEX(บันทึกสต็อครายวัน!$D$122:$D$9999,MATCH(TEXT($B$2,"YYYYMMDD")&"|"&$E$2&"|"&B7,บันทึกสต็อครายวัน!$M$122:$M$9999,0))),IFERROR(IF(SUMPRODUCT(MAX((บันทึกสต็อครายวัน!$A$122:$A$9999<$B$2)*(บันทึกสต็อครายวัน!$B$122:$B$9999=$E$2)*(บันทึกสต็อครายวัน!$C$122:$C$9999=B7)*บันทึกสต็อครายวัน!$A$122:$A$9999))=0,"",INDEX(บันทึกสต็อครายวัน!$I$122:$I$9999,MATCH(TEXT(SUMPRODUCT(MAX((บันทึกสต็อครายวัน!$A$122:$A$9999<$B$2)*(บันทึกสต็อครายวัน!$B$122:$B$9999=$E$2)*(บันทึกสต็อครายวัน!$C$122:$C$9999=B7)*บันทึกสต็อครายวัน!$A$122:$A$9999)),"YYYYMMDD")&"|"&$E$2&"|"&B7,บันทึกสต็อครายวัน!$M$122:$M$9999,0))),"")) -> 0 | E7: =IFERROR(IF(INDEX(บันทึกสต็อครายวัน!$E$122:$E$9999,MATCH(TEXT($B$2,"YYYYMMDD")&"|"&$E$2&"|"&B7,บันทึกสต็อครายวัน!$M$122:$M$9999,0))="",IFERROR(IF(SUMPRODUCT(MAX((บันทึกสต็อครายวัน!$A$122:$A$9999<$B$2)*(บันทึกสต็อครายวัน!$B$122:$B$9999=$E$2)*(บันทึกสต็อครายวัน!$C$122:$C$9999=B7)*บันทึกสต็อครายวัน!$A$122:$A$9999))=0,"",INDEX(บันทึกสต็อครายวัน!$J$122:$J$9999,MATCH(TEXT(SUMPRODUCT(MAX((บันทึกสต็อครายวัน!$A$122:$A$9999<$B$2)*(บันทึกสต็อครายวัน!$B$122:$B$9999=$E$2)*(บันทึกสต็อครายวัน!$C$122:$C$9999=B7)*บันทึกสต็อครายวัน!$A$122:$A$9999)),"YYYYMMDD")&"|"&$E$2&"|"&B7,บันทึกสต็อครายวัน!$M$122:$M$9999,0))),""),INDEX(บันทึกสต็อครายวัน!$E$122:$E$9999,MATCH(TEXT($B$2,"YYYYMMDD")&"|"&$E$2&"|"&B7,บันทึกสต็อครายวัน!$M$122:$M$9999,0))),IFERROR(IF(SUMPRODUCT(MAX((บันทึกสต็อครายวัน!$A$122:$A$9999<$B$2)*(บันทึกสต็อครายวัน!$B$122:$B$9999=$E$2)*(บันทึกสต็อครายวัน!$C$122:$C$9999=B7)*บันทึกสต็อครายวัน!$A$122:$A$9999))=0,"",INDEX(บันทึกสต็อครายวัน!$J$122:$J$9999,MATCH(TEXT(SUMPRODUCT(MAX((บันทึกสต็อครายวัน!$A$122:$A$9999<$B$2)*(บันทึกสต็อครายวัน!$B$122:$B$9999=$E$2)*(บันทึกสต็อครายวัน!$C$122:$C$9999=B7)*บันทึกสต็อครายวัน!$A$122:$A$9999)),"YYYYMMDD")&"|"&$E$2&"|"&B7,บันทึกสต็อครายวัน!$M$122:$M$9999,0))),"")) -> 0 | F7: =IFERROR(IF(ISBLANK(INDEX(บันทึกสต็อครายวัน!$F$122:$F$9999,MATCH(TEXT($B$2,"YYYYMMDD")&"|"&$E$2&"|"&B7,บันทึกสต็อครายวัน!$M$122:$M$9999,0))),"",INDEX(บันทึกสต็อครายวัน!$F$122:$F$9999,MATCH(TEXT($B$2,"YYYYMMDD")&"|"&$E$2&"|"&B7,บันทึกสต็อครายวัน!$M$122:$M$9999,0))),"") | G7: =IFERROR(IF(ISBLANK(INDEX(บันทึกสต็อครายวัน!$G$122:$G$9999,MATCH(TEXT($B$2,"YYYYMMDD")&"|"&$E$2&"|"&B7,บันทึกสต็อครายวัน!$M$122:$M$9999,0))),"",INDEX(บันทึกสต็อครายวัน!$G$122:$G$9999,MATCH(TEXT($B$2,"YYYYMMDD")&"|"&$E$2&"|"&B7,บันทึกสต็อครายวัน!$M$122:$M$9999,0))),"") | H7: =IFERROR(IF(ISBLANK(INDEX(บันทึกสต็อครายวัน!$H$122:$H$9999,MATCH(TEXT($B$2,"YYYYMMDD")&"|"&$E$2&"|"&B7,บันทึกสต็อครายวัน!$M$122:$M$9999,0))),"",INDEX(บันทึกสต็อครายวัน!$H$122:$H$9999,MATCH(TEXT($B$2,"YYYYMMDD")&"|"&$E$2&"|"&B7,บันทึกสต็อครายวัน!$M$122:$M$9999,0))),"") | I7: =IFERROR(IF(ISBLANK(INDEX(บันทึกสต็อครายวัน!$I$122:$I$9999,MATCH(TEXT($B$2,"YYYYMMDD")&"|"&$E$2&"|"&B7,บันทึกสต็อครายวัน!$M$122:$M$9999,0))),"",INDEX(บันทึกสต็อครายวัน!$I$122:$I$9999,MATCH(TEXT($B$2,"YYYYMMDD")&"|"&$E$2&"|"&B7,บันทึกสต็อครายวัน!$M$122:$M$9999,0))),"") | J7: =IFERROR(IF(ISBLANK(INDEX(บันทึกสต็อครายวัน!$J$122:$J$9999,MATCH(TEXT($B$2,"YYYYMMDD")&"|"&$E$2&"|"&B7,บันทึกสต็อครายวัน!$M$122:$M$9999,0))),"",INDEX(บันทึกสต็อครายวัน!$J$122:$J$9999,MATCH(TEXT($B$2,"YYYYMMDD")&"|"&$E$2&"|"&B7,บันทึกสต็อครายวัน!$M$122:$M$9999,0))),"") | K7: =IFERROR(IF(ISBLANK(INDEX(บันทึกสต็อครายวัน!$K$122:$K$9999,MATCH(TEXT($B$2,"YYYYMMDD")&"|"&$E$2&"|"&B7,บันทึกสต็อครายวัน!$M$122:$M$9999,0))),"",INDEX(บันทึกสต็อครายวัน!$K$122:$K$9999,MATCH(TEXT($B$2,"YYYYMMDD")&"|"&$E$2&"|"&B7,บันทึกสต็อครายวัน!$M$122:$M$9999,0))),"") | L7: =IFERROR(IF(ISBLANK(INDEX(บันทึกสต็อครายวัน!$L$122:$L$9999,MATCH(TEXT($B$2,"YYYYMMDD")&"|"&$E$2&"|"&B7,บันทึกสต็อครายวัน!$M$122:$M$9999,0))),"",INDEX(บันทึกสต็อครายวัน!$L$122:$L$9999,MATCH(TEXT($B$2,"YYYYMMDD")&"|"&$E$2&"|"&B7,บันทึกสต็อครายวัน!$M$122:$M$9999,0))),"")
A8: Yogurt 1kg/Box | B8: Vanilla | C8: 1kg/Box | D8: =IFERROR(IF(INDEX(บันทึกสต็อครายวัน!$D$122:$D$9999,MATCH(TEXT($B$2,"YYYYMMDD")&"|"&$E$2&"|"&B8,บันทึกสต็อครายวัน!$M$122:$M$9999,0))="",IFERROR(IF(SUMPRODUCT(MAX((บันทึกสต็อครายวัน!$A$122:$A$9999<$B$2)*(บันทึกสต็อครายวัน!$B$122:$B$9999=$E$2)*(บันทึกสต็อครายวัน!$C$122:$C$9999=B8)*บันทึกสต็อครายวัน!$A$122:$A$9999))=0,"",INDEX(บันทึกสต็อครายวัน!$I$122:$I$9999,MATCH(TEXT(SUMPRODUCT(MAX((บันทึกสต็อครายวัน!$A$122:$A$9999<$B$2)*(บันทึกสต็อครายวัน!$B$122:$B$9999=$E$2)*(บันทึกสต็อครายวัน!$C$122:$C$9999=B8)*บันทึกสต็อครายวัน!$A$122:$A$9999)),"YYYYMMDD")&"|"&$E$2&"|"&B8,บันทึกสต็อครายวัน!$M$122:$M$9999,0))),""),INDEX(บันทึกสต็อครายวัน!$D$122:$D$9999,MATCH(TEXT($B$2,"YYYYMMDD")&"|"&$E$2&"|"&B8,บันทึกสต็อครายวัน!$M$122:$M$9999,0))),IFERROR(IF(SUMPRODUCT(MAX((บันทึกสต็อครายวัน!$A$122:$A$9999<$B$2)*(บันทึกสต็อครายวัน!$B$122:$B$9999=$E$2)*(บันทึกสต็อครายวัน!$C$122:$C$9999=B8)*บันทึกสต็อครายวัน!$A$122:$A$9999))=0,"",INDEX(บันทึกสต็อครายวัน!$I$122:$I$9999,MATCH(TEXT(SUMPRODUCT(MAX((บันทึกสต็อครายวัน!$A$122:$A$9999<$B$2)*(บันทึกสต็อครายวัน!$B$122:$B$9999=$E$2)*(บันทึกสต็อครายวัน!$C$122:$C$9999=B8)*บันทึกสต็อครายวัน!$A$122:$A$9999)),"YYYYMMDD")&"|"&$E$2&"|"&B8,บันทึกสต็อครายวัน!$M$122:$M$9999,0))),"")) -> 0 | E8: =IFERROR(IF(INDEX(บันทึกสต็อครายวัน!$E$122:$E$9999,MATCH(TEXT($B$2,"YYYYMMDD")&"|"&$E$2&"|"&B8,บันทึกสต็อครายวัน!$M$122:$M$9999,0))="",IFERROR(IF(SUMPRODUCT(MAX((บันทึกสต็อครายวัน!$A$122:$A$9999<$B$2)*(บันทึกสต็อครายวัน!$B$122:$B$9999=$E$2)*(บันทึกสต็อครายวัน!$C$122:$C$9999=B8)*บันทึกสต็อครายวัน!$A$122:$A$9999))=0,"",INDEX(บันทึกสต็อครายวัน!$J$122:$J$9999,MATCH(TEXT(SUMPRODUCT(MAX((บันทึกสต็อครายวัน!$A$122:$A$9999<$B$2)*(บันทึกสต็อครายวัน!$B$122:$B$9999=$E$2)*(บันทึกสต็อครายวัน!$C$122:$C$9999=B8)*บันทึกสต็อครายวัน!$A$122:$A$9999)),"YYYYMMDD")&"|"&$E$2&"|"&B8,บันทึกสต็อครายวัน!$M$122:$M$9999,0))),""),INDEX(บันทึกสต็อครายวัน!$E$122:$E$9999,MATCH(TEXT($B$2,"YYYYMMDD")&"|"&$E$2&"|"&B8,บันทึกสต็อครายวัน!$M$122:$M$9999,0))),IFERROR(IF(SUMPRODUCT(MAX((บันทึกสต็อครายวัน!$A$122:$A$9999<$B$2)*(บันทึกสต็อครายวัน!$B$122:$B$9999=$E$2)*(บันทึกสต็อครายวัน!$C$122:$C$9999=B8)*บันทึกสต็อครายวัน!$A$122:$A$9999))=0,"",INDEX(บันทึกสต็อครายวัน!$J$122:$J$9999,MATCH(TEXT(SUMPRODUCT(MAX((บันทึกสต็อครายวัน!$A$122:$A$9999<$B$2)*(บันทึกสต็อครายวัน!$B$122:$B$9999=$E$2)*(บันทึกสต็อครายวัน!$C$122:$C$9999=B8)*บันทึกสต็อครายวัน!$A$122:$A$9999)),"YYYYMMDD")&"|"&$E$2&"|"&B8,บันทึกสต็อครายวัน!$M$122:$M$9999,0))),"")) -> 981 | F8: =IFERROR(IF(ISBLANK(INDEX(บันทึกสต็อครายวัน!$F$122:$F$9999,MATCH(TEXT($B$2,"YYYYMMDD")&"|"&$E$2&"|"&B8,บันทึกสต็อครายวัน!$M$122:$M$9999,0))),"",INDEX(บันทึกสต็อครายวัน!$F$122:$F$9999,MATCH(TEXT($B$2,"YYYYMMDD")&"|"&$E$2&"|"&B8,บันทึกสต็อครายวัน!$M$122:$M$9999,0))),"") | G8: =IFERROR(IF(ISBLANK(INDEX(บันทึกสต็อครายวัน!$G$122:$G$9999,MATCH(TEXT($B$2,"YYYYMMDD")&"|"&$E$2&"|"&B8,บันทึกสต็อครายวัน!$M$122:$M$9999,0))),"",INDEX(บันทึกสต็อครายวัน!$G$122:$G$9999,MATCH(TEXT($B$2,"YYYYMMDD")&"|"&$E$2&"|"&B8,บันทึกสต็อครายวัน!$M$122:$M$9999,0))),"") | H8: =IFERROR(IF(ISBLANK(INDEX(บันทึกสต็อครายวัน!$H$122:$H$9999,MATCH(TEXT($B$2,"YYYYMMDD")&"|"&$E$2&"|"&B8,บันทึกสต็อครายวัน!$M$122:$M$9999,0))),"",INDEX(บันทึกสต็อครายวัน!$H$122:$H$9999,MATCH(TEXT($B$2,"YYYYMMDD")&"|"&$E$2&"|"&B8,บันทึกสต็อครายวัน!$M$122:$M$9999,0))),"") | I8: =IFERROR(IF(ISBLANK(INDEX(บันทึกสต็อครายวัน!$I$122:$I$9999,MATCH(TEXT($B$2,"YYYYMMDD")&"|"&$E$2&"|"&B8,บันทึกสต็อครายวัน!$M$122:$M$9999,0))),"",INDEX(บันทึกสต็อครายวัน!$I$122:$I$9999,MATCH(TEXT($B$2,"YYYYMMDD")&"|"&$E$2&"|"&B8,บันทึกสต็อครายวัน!$M$122:$M$9999,0))),"") | J8: =IFERROR(IF(ISBLANK(INDEX(บันทึกสต็อครายวัน!$J$122:$J$9999,MATCH(TEXT($B$2,"YYYYMMDD")&"|"&$E$2&"|"&B8,บันทึกสต็อครายวัน!$M$122:$M$9999,0))),"",INDEX(บันทึกสต็อครายวัน!$J$122:$J$9999,MATCH(TEXT($B$2,"YYYYMMDD")&"|"&$E$2&"|"&B8,บันทึกสต็อครายวัน!$M$122:$M$9999,0))),"") | K8: =IFERROR(IF(ISBLANK(INDEX(บันทึกสต็อครายวัน!$K$122:$K$9999,MATCH(TEXT($B$2,"YYYYMMDD")&"|"&$E$2&"|"&B8,บันทึกสต็อครายวัน!$M$122:$M$9999,0))),"",INDEX(บันทึกสต็อครายวัน!$K$122:$K$9999,MATCH(TEXT($B$2,"YYYYMMDD")&"|"&$E$2&"|"&B8,บันทึกสต็อครายวัน!$M$122:$M$9999,0))),"") | L8: =IFERROR(IF(ISBLANK(INDEX(บันทึกสต็อครายวัน!$L$122:$L$9999,MATCH(TEXT($B$2,"YYYYMMDD")&"|"&$E$2&"|"&B8,บันทึกสต็อครายวัน!$M$122:$M$9999,0))),"",INDEX(บันทึกสต็อครายวัน!$L$122:$L$9999,MATCH(TEXT($B$2,"YYYYMMDD")&"|"&$E$2&"|"&B8,บันทึกสต็อครายวัน!$M$122:$M$9999,0))),"")
A9: Yogurt 1kg/Box | B9: Pineapple | C9: 1kg/Box | D9: =IFERROR(IF(INDEX(บันทึกสต็อครายวัน!$D$122:$D$9999,MATCH(TEXT($B$2,"YYYYMMDD")&"|"&$E$2&"|"&B9,บันทึกสต็อครายวัน!$M$122:$M$9999,0))="",IFERROR(IF(SUMPRODUCT(MAX((บันทึกสต็อครายวัน!$A$122:$A$9999<$B$2)*(บันทึกสต็อครายวัน!$B$122:$B$9999=$E$2)*(บันทึกสต็อครายวัน!$C$122:$C$9999=B9)*บันทึกสต็อครายวัน!$A$122:$A$9999))=0,"",INDEX(บันทึกสต็อครายวัน!$I$122:$I$9999,MATCH(TEXT(SUMPRODUCT(MAX((บันทึกสต็อครายวัน!$A$122:$A$9999<$B$2)*(บันทึกสต็อครายวัน!$B$122:$B$9999=$E$2)*(บันทึกสต็อครายวัน!$C$122:$C$9999=B9)*บันทึกสต็อครายวัน!$A$122:$A$9999)),"YYYYMMDD")&"|"&$E$2&"|"&B9,บันทึกสต็อครายวัน!$M$122:$M$9999,0))),""),INDEX(บันทึกสต็อครายวัน!$D$122:$D$9999,MATCH(TEXT($B$2,"YYYYMMDD")&"|"&$E$2&"|"&B9,บันทึกสต็อครายวัน!$M$122:$M$9999,0))),IFERROR(IF(SUMPRODUCT(MAX((บันทึกสต็อครายวัน!$A$122:$A$9999<$B$2)*(บันทึกสต็อครายวัน!$B$122:$B$9999=$E$2)*(บันทึกสต็อครายวัน!$C$122:$C$9999=B9)*บันทึกสต็อครายวัน!$A$122:$A$9999))=0,"",INDEX(บันทึกสต็อครายวัน!$I$122:$I$9999,MATCH(TEXT(SUMPRODUCT(MAX((บันทึกสต็อครายวัน!$A$122:$A$9999<$B$2)*(บันทึกสต็อครายวัน!$B$122:$B$9999=$E$2)*(บันทึกสต็อครายวัน!$C$122:$C$9999=B9)*บันทึกสต็อครายวัน!$A$122:$A$9999)),"YYYYMMDD")&"|"&$E$2&"|"&B9,บันทึกสต็อครายวัน!$M$122:$M$9999,0))),"")) -> 1 | E9: =IFERROR(IF(INDEX(บันทึกสต็อครายวัน!$E$122:$E$9999,MATCH(TEXT($B$2,"YYYYMMDD")&"|"&$E$2&"|"&B9,บันทึกสต็อครายวัน!$M$122:$M$9999,0))="",IFERROR(IF(SUMPRODUCT(MAX((บันทึกสต็อครายวัน!$A$122:$A$9999<$B$2)*(บันทึกสต็อครายวัน!$B$122:$B$9999=$E$2)*(บันทึกสต็อครายวัน!$C$122:$C$9999=B9)*บันทึกสต็อครายวัน!$A$122:$A$9999))=0,"",INDEX(บันทึกสต็อครายวัน!$J$122:$J$9999,MATCH(TEXT(SUMPRODUCT(MAX((บันทึกสต็อครายวัน!$A$122:$A$9999<$B$2)*(บันทึกสต็อครายวัน!$B$122:$B$9999=$E$2)*(บันทึกสต็อครายวัน!$C$122:$C$9999=B9)*บันทึกสต็อครายวัน!$A$122:$A$9999)),"YYYYMMDD")&"|"&$E$2&"|"&B9,บันทึกสต็อครายวัน!$M$122:$M$9999,0))),""),INDEX(บันทึกสต็อครายวัน!$E$122:$E$9999,MATCH(TEXT($B$2,"YYYYMMDD")&"|"&$E$2&"|"&B9,บันทึกสต็อครายวัน!$M$122:$M$9999,0))),IFERROR(IF(SUMPRODUCT(MAX((บันทึกสต็อครายวัน!$A$122:$A$9999<$B$2)*(บันทึกสต็อครายวัน!$B$122:$B$9999=$E$2)*(บันทึกสต็อครายวัน!$C$122:$C$9999=B9)*บันทึกสต็อครายวัน!$A$122:$A$9999))=0,"",INDEX(บันทึกสต็อครายวัน!$J$122:$J$9999,MATCH(TEXT(SUMPRODUCT(MAX((บันทึกสต็อครายวัน!$A$122:$A$9999<$B$2)*(บันทึกสต็อครายวัน!$B$122:$B$9999=$E$2)*(บันทึกสต็อครายวัน!$C$122:$C$9999=B9)*บันทึกสต็อครายวัน!$A$122:$A$9999)),"YYYYMMDD")&"|"&$E$2&"|"&B9,บันทึกสต็อครายวัน!$M$122:$M$9999,0))),"")) -> 532 | F9: =IFERROR(IF(ISBLANK(INDEX(บันทึกสต็อครายวัน!$F$122:$F$9999,MATCH(TEXT($B$2,"YYYYMMDD")&"|"&$E$2&"|"&B9,บันทึกสต็อครายวัน!$M$122:$M$9999,0))),"",INDEX(บันทึกสต็อครายวัน!$F$122:$F$9999,MATCH(TEXT($B$2,"YYYYMMDD")&"|"&$E$2&"|"&B9,บันทึกสต็อครายวัน!$M$122:$M$9999,0))),"") | G9: =IFERROR(IF(ISBLANK(INDEX(บันทึกสต็อครายวัน!$G$122:$G$9999,MATCH(TEXT($B$2,"YYYYMMDD")&"|"&$E$2&"|"&B9,บันทึกสต็อครายวัน!$M$122:$M$9999,0))),"",INDEX(บันทึกสต็อครายวัน!$G$122:$G$9999,MATCH(TEXT($B$2,"YYYYMMDD")&"|"&$E$2&"|"&B9,บันทึกสต็อครายวัน!$M$122:$M$9999,0))),"") | H9: =IFERROR(IF(ISBLANK(INDEX(บันทึกสต็อครายวัน!$H$122:$H$9999,MATCH(TEXT($B$2,"YYYYMMDD")&"|"&$E$2&"|"&B9,บันทึกสต็อครายวัน!$M$122:$M$9999,0))),"",INDEX(บันทึกสต็อครายวัน!$H$122:$H$9999,MATCH(TEXT($B$2,"YYYYMMDD")&"|"&$E$2&"|"&B9,บันทึกสต็อครายวัน!$M$122:$M$9999,0))),"") | I9: =IFERROR(IF(ISBLANK(INDEX(บันทึกสต็อครายวัน!$I$122:$I$9999,MATCH(TEXT($B$2,"YYYYMMDD")&"|"&$E$2&"|"&B9,บันทึกสต็อครายวัน!$M$122:$M$9999,0))),"",INDEX(บันทึกสต็อครายวัน!$I$122:$I$9999,MATCH(TEXT($B$2,"YYYYMMDD")&"|"&$E$2&"|"&B9,บันทึกสต็อครายวัน!$M$122:$M$9999,0))),"") | J9: =IFERROR(IF(ISBLANK(INDEX(บันทึกสต็อครายวัน!$J$122:$J$9999,MATCH(TEXT($B$2,"YYYYMMDD")&"|"&$E$2&"|"&B9,บันทึกสต็อครายวัน!$M$122:$M$9999,0))),"",INDEX(บันทึกสต็อครายวัน!$J$122:$J$9999,MATCH(TEXT($B$2,"YYYYMMDD")&"|"&$E$2&"|"&B9,บันทึกสต็อครายวัน!$M$122:$M$9999,0))),"") | K9: =IFERROR(IF(ISBLANK(INDEX(บันทึกสต็อครายวัน!$K$122:$K$9999,MATCH(TEXT($B$2,"YYYYMMDD")&"|"&$E$2&"|"&B9,บันทึกสต็อครายวัน!$M$122:$M$9999,0))),"",INDEX(บันทึกสต็อครายวัน!$K$122:$K$9999,MATCH(TEXT($B$2,"YYYYMMDD")&"|"&$E$2&"|"&B9,บันทึกสต็อครายวัน!$M$122:$M$9999,0))),"") | L9: =IFERROR(IF(ISBLANK(INDEX(บันทึกสต็อครายวัน!$L$122:$L$9999,MATCH(TEXT($B$2,"YYYYMMDD")&"|"&$E$2&"|"&B9,บันทึกสต็อครายวัน!$M$122:$M$9999,0))),"",INDEX(บันทึกสต็อครายวัน!$L$122:$L$9999,MATCH(TEXT($B$2,"YYYYMMDD")&"|"&$E$2&"|"&B9,บันทึกสต็อครายวัน!$M$122:$M$9999,0))),"")
A10: Yogurt 1kg/Box | B10: Biscoff | C10: 1kg/Box | D10: =IFERROR(IF(INDEX(บันทึกสต็อครายวัน!$D$122:$D$9999,MATCH(TEXT($B$2,"YYYYMMDD")&"|"&$E$2&"|"&B10,บันทึกสต็อครายวัน!$M$122:$M$9999,0))="",IFERROR(IF(SUMPRODUCT(MAX((บันทึกสต็อครายวัน!$A$122:$A$9999<$B$2)*(บันทึกสต็อครายวัน!$B$122:$B$9999=$E$2)*(บันทึกสต็อครายวัน!$C$122:$C$9999=B10)*บันทึกสต็อครายวัน!$A$122:$A$9999))=0,"",INDEX(บันทึกสต็อครายวัน!$I$122:$I$9999,MATCH(TEXT(SUMPRODUCT(MAX((บันทึกสต็อครายวัน!$A$122:$A$9999<$B$2)*(บันทึกสต็อครายวัน!$B$122:$B$9999=$E$2)*(บันทึกสต็อครายวัน!$C$122:$C$9999=B10)*บันทึกสต็อครายวัน!$A$122:$A$9999)),"YYYYMMDD")&"|"&$E$2&"|"&B10,บันทึกสต็อครายวัน!$M$122:$M$9999,0))),""),INDEX(บันทึกสต็อครายวัน!$D$122:$D$9999,MATCH(TEXT($B$2,"YYYYMMDD")&"|"&$E$2&"|"&B10,บันทึกสต็อครายวัน!$M$122:$M$9999,0))),IFERROR(IF(SUMPRODUCT(MAX((บันทึกสต็อครายวัน!$A$122:$A$9999<$B$2)*(บันทึกสต็อครายวัน!$B$122:$B$9999=$E$2)*(บันทึกสต็อครายวัน!$C$122:$C$9999=B10)*บันทึกสต็อครายวัน!$A$122:$A$9999))=0,"",INDEX(บันทึกสต็อครายวัน!$I$122:$I$9999,MATCH(TEXT(SUMPRODUCT(MAX((บันทึกสต็อครายวัน!$A$122:$A$9999<$B$2)*(บันทึกสต็อครายวัน!$B$122:$B$9999=$E$2)*(บันทึกสต็อครายวัน!$C$122:$C$9999=B10)*บันทึกสต็อครายวัน!$A$122:$A$9999)),"YYYYMMDD")&"|"&$E$2&"|"&B10,บันทึกสต็อครายวัน!$M$122:$M$9999,0))),"")) -> 0 | E10: =IFERROR(IF(INDEX(บันทึกสต็อครายวัน!$E$122:$E$9999,MATCH(TEXT($B$2,"YYYYMMDD")&"|"&$E$2&"|"&B10,บันทึกสต็อครายวัน!$M$122:$M$9999,0))="",IFERROR(IF(SUMPRODUCT(MAX((บันทึกสต็อครายวัน!$A$122:$A$9999<$B$2)*(บันทึกสต็อครายวัน!$B$122:$B$9999=$E$2)*(บันทึกสต็อครายวัน!$C$122:$C$9999=B10)*บันทึกสต็อครายวัน!$A$122:$A$9999))=0,"",INDEX(บันทึกสต็อครายวัน!$J$122:$J$9999,MATCH(TEXT(SUMPRODUCT(MAX((บันทึกสต็อครายวัน!$A$122:$A$9999<$B$2)*(บันทึกสต็อครายวัน!$B$122:$B$9999=$E$2)*(บันทึกสต็อครายวัน!$C$122:$C$9999=B10)*บันทึกสต็อครายวัน!$A$122:$A$9999)),"YYYYMMDD")&"|"&$E$2&"|"&B10,บันทึกสต็อครายวัน!$M$122:$M$9999,0))),""),INDEX(บันทึกสต็อครายวัน!$E$122:$E$9999,MATCH(TEXT($B$2,"YYYYMMDD")&"|"&$E$2&"|"&B10,บันทึกสต็อครายวัน!$M$122:$M$9999,0))),IFERROR(IF(SUMPRODUCT(MAX((บันทึกสต็อครายวัน!$A$122:$A$9999<$B$2)*(บันทึกสต็อครายวัน!$B$122:$B$9999=$E$2)*(บันทึกสต็อครายวัน!$C$122:$C$9999=B10)*บันทึกสต็อครายวัน!$A$122:$A$9999))=0,"",INDEX(บันทึกสต็อครายวัน!$J$122:$J$9999,MATCH(TEXT(SUMPRODUCT(MAX((บันทึกสต็อครายวัน!$A$122:$A$9999<$B$2)*(บันทึกสต็อครายวัน!$B$122:$B$9999=$E$2)*(บันทึกสต็อครายวัน!$C$122:$C$9999=B10)*บันทึกสต็อครายวัน!$A$122:$A$9999)),"YYYYMMDD")&"|"&$E$2&"|"&B10,บันทึกสต็อครายวัน!$M$122:$M$9999,0))),"")) -> 429 | F10: =IFERROR(IF(ISBLANK(INDEX(บันทึกสต็อครายวัน!$F$122:$F$9999,MATCH(TEXT($B$2,"YYYYMMDD")&"|"&$E$2&"|"&B10,บันทึกสต็อครายวัน!$M$122:$M$9999,0))),"",INDEX(บันทึกสต็อครายวัน!$F$122:$F$9999,MATCH(TEXT($B$2,"YYYYMMDD")&"|"&$E$2&"|"&B10,บันทึกสต็อครายวัน!$M$122:$M$9999,0))),"") | G10: =IFERROR(IF(ISBLANK(INDEX(บันทึกสต็อครายวัน!$G$122:$G$9999,MATCH(TEXT($B$2,"YYYYMMDD")&"|"&$E$2&"|"&B10,บันทึกสต็อครายวัน!$M$122:$M$9999,0))),"",INDEX(บันทึกสต็อครายวัน!$G$122:$G$9999,MATCH(TEXT($B$2,"YYYYMMDD")&"|"&$E$2&"|"&B10,บันทึกสต็อครายวัน!$M$122:$M$9999,0))),"") | H10: =IFERROR(IF(ISBLANK(INDEX(บันทึกสต็อครายวัน!$H$122:$H$9999,MATCH(TEXT($B$2,"YYYYMMDD")&"|"&$E$2&"|"&B10,บันทึกสต็อครายวัน!$M$122:$M$9999,0))),"",INDEX(บันทึกสต็อครายวัน!$H$122:$H$9999,MATCH(TEXT($B$2,"YYYYMMDD")&"|"&$E$2&"|"&B10,บันทึกสต็อครายวัน!$M$122:$M$9999,0))),"") | I10: =IFERROR(IF(ISBLANK(INDEX(บันทึกสต็อครายวัน!$I$122:$I$9999,MATCH(TEXT($B$2,"YYYYMMDD")&"|"&$E$2&"|"&B10,บันทึกสต็อครายวัน!$M$122:$M$9999,0))),"",INDEX(บันทึกสต็อครายวัน!$I$122:$I$9999,MATCH(TEXT($B$2,"YYYYMMDD")&"|"&$E$2&"|"&B10,บันทึกสต็อครายวัน!$M$122:$M$9999,0))),"") | J10: =IFERROR(IF(ISBLANK(INDEX(บันทึกสต็อครายวัน!$J$122:$J$9999,MATCH(TEXT($B$2,"YYYYMMDD")&"|"&$E$2&"|"&B10,บันทึกสต็อครายวัน!$M$122:$M$9999,0))),"",INDEX(บันทึกสต็อครายวัน!$J$122:$J$9999,MATCH(TEXT($B$2,"YYYYMMDD")&"|"&$E$2&"|"&B10,บันทึกสต็อครายวัน!$M$122:$M$9999,0))),"") | K10: =IFERROR(IF(ISBLANK(INDEX(บันทึกสต็อครายวัน!$K$122:$K$9999,MATCH(TEXT($B$2,"YYYYMMDD")&"|"&$E$2&"|"&B10,บันทึกสต็อครายวัน!$M$122:$M$9999,0))),"",INDEX(บันทึกสต็อครายวัน!$K$122:$K$9999,MATCH(TEXT($B$2,"YYYYMMDD")&"|"&$E$2&"|"&B10,บันทึกสต็อครายวัน!$M$122:$M$9999,0))),"") | L10: =IFERROR(IF(ISBLANK(INDEX(บันทึกสต็อครายวัน!$L$122:$L$9999,MATCH(TEXT($B$2,"YYYYMMDD")&"|"&$E$2&"|"&B10,บันทึกสต็อครายวัน!$M$122:$M$9999,0))),"",INDEX(บันทึกสต็อครายวัน!$L$122:$L$9999,MATCH(TEXT($B$2,"YYYYMMDD")&"|"&$E$2&"|"&B10,บันทึกสต็อครายวัน!$M$122:$M$9999,0))),"")
A11: Yogurt 1kg/Box | B11: Overnight oats biscoff | C11: 1kg/Box | D11: =IFERROR(IF(INDEX(บันทึกสต็อครายวัน!$D$122:$D$9999,MATCH(TEXT($B$2,"YYYYMMDD")&"|"&$E$2&"|"&B11,บันทึกสต็อครายวัน!$M$122:$M$9999,0))="",IFERROR(IF(SUMPRODUCT(MAX((บันทึกสต็อครายวัน!$A$122:$A$9999<$B$2)*(บันทึกสต็อครายวัน!$B$122:$B$9999=$E$2)*(บันทึกสต็อครายวัน!$C$122:$C$9999=B11)*บันทึกสต็อครายวัน!$A$122:$A$9999))=0,"",INDEX(บันทึกสต็อครายวัน!$I$122:$I$9999,MATCH(TEXT(SUMPRODUCT(MAX((บันทึกสต็อครายวัน!$A$122:$A$9999<$B$2)*(บันทึกสต็อครายวัน!$B$122:$B$9999=$E$2)*(บันทึกสต็อครายวัน!$C$122:$C$9999=B11)*บันทึกสต็อครายวัน!$A$122:$A$9999)),"YYYYMMDD")&"|"&$E$2&"|"&B11,บันทึกสต็อครายวัน!$M$122:$M$9999,0))),""),INDEX(บันทึกสต็อครายวัน!$D$122:$D$9999,MATCH(TEXT($B$2,"YYYYMMDD")&"|"&$E$2&"|"&B11,บันทึกสต็อครายวัน!$M$122:$M$9999,0))),IFERROR(IF(SUMPRODUCT(MAX((บันทึกสต็อครายวัน!$A$122:$A$9999<$B$2)*(บันทึกสต็อครายวัน!$B$122:$B$9999=$E$2)*(บันทึกสต็อครายวัน!$C$122:$C$9999=B11)*บันทึกสต็อครายวัน!$A$122:$A$9999))=0,"",INDEX(บันทึกสต็อครายวัน!$I$122:$I$9999,MATCH(TEXT(SUMPRODUCT(MAX((บันทึกสต็อครายวัน!$A$122:$A$9999<$B$2)*(บันทึกสต็อครายวัน!$B$122:$B$9999=$E$2)*(บันทึกสต็อครายวัน!$C$122:$C$9999=B11)*บันทึกสต็อครายวัน!$A$122:$A$9999)),"YYYYMMDD")&"|"&$E$2&"|"&B11,บันทึกสต็อครายวัน!$M$122:$M$9999,0))),"")) -> 1 | E11: =IFERROR(IF(INDEX(บันทึกสต็อครายวัน!$E$122:$E$9999,MATCH(TEXT($B$2,"YYYYMMDD")&"|"&$E$2&"|"&B11,บันทึกสต็อครายวัน!$M$122:$M$9999,0))="",IFERROR(IF(SUMPRODUCT(MAX((บันทึกสต็อครายวัน!$A$122:$A$9999<$B$2)*(บันทึกสต็อครายวัน!$B$122:$B$9999=$E$2)*(บันทึกสต็อครายวัน!$C$122:$C$9999=B11)*บันทึกสต็อครายวัน!$A$122:$A$9999))=0,"",INDEX(บันทึกสต็อครายวัน!$J$122:$J$9999,MATCH(TEXT(SUMPRODUCT(MAX((บันทึกสต็อครายวัน!$A$122:$A$9999<$B$2)*(บันทึกสต็อครายวัน!$B$122:$B$9999=$E$2)*(บันทึกสต็อครายวัน!$C$122:$C$9999=B11)*บันทึกสต็อครายวัน!$A$122:$A$9999)),"YYYYMMDD")&"|"&$E$2&"|"&B11,บันทึกสต็อครายวัน!$M$122:$M$9999,0))),""),INDEX(บันทึกสต็อครายวัน!$E$122:$E$9999,MATCH(TEXT($B$2,"YYYYMMDD")&"|"&$E$2&"|"&B11,บันทึกสต็อครายวัน!$M$122:$M$9999,0))),IFERROR(IF(SUMPRODUCT(MAX((บันทึกสต็อครายวัน!$A$122:$A$9999<$B$2)*(บันทึกสต็อครายวัน!$B$122:$B$9999=$E$2)*(บันทึกสต็อครายวัน!$C$122:$C$9999=B11)*บันทึกสต็อครายวัน!$A$122:$A$9999))=0,"",INDEX(บันทึกสต็อครายวัน!$J$122:$J$9999,MATCH(TEXT(SUMPRODUCT(MAX((บันทึกสต็อครายวัน!$A$122:$A$9999<$B$2)*(บันทึกสต็อครายวัน!$B$122:$B$9999=$E$2)*(บันทึกสต็อครายวัน!$C$122:$C$9999=B11)*บันทึกสต็อครายวัน!$A$122:$A$9999)),"YYYYMMDD")&"|"&$E$2&"|"&B11,บันทึกสต็อครายวัน!$M$122:$M$9999,0))),"")) -> 956 | F11: =IFERROR(IF(ISBLANK(INDEX(บันทึกสต็อครายวัน!$F$122:$F$9999,MATCH(TEXT($B$2,"YYYYMMDD")&"|"&$E$2&"|"&B11,บันทึกสต็อครายวัน!$M$122:$M$9999,0))),"",INDEX(บันทึกสต็อครายวัน!$F$122:$F$9999,MATCH(TEXT($B$2,"YYYYMMDD")&"|"&$E$2&"|"&B11,บันทึกสต็อครายวัน!$M$122:$M$9999,0))),"") | G11: =IFERROR(IF(ISBLANK(INDEX(บันทึกสต็อครายวัน!$G$122:$G$9999,MATCH(TEXT($B$2,"YYYYMMDD")&"|"&$E$2&"|"&B11,บันทึกสต็อครายวัน!$M$122:$M$9999,0))),"",INDEX(บันทึกสต็อครายวัน!$G$122:$G$9999,MATCH(TEXT($B$2,"YYYYMMDD")&"|"&$E$2&"|"&B11,บันทึกสต็อครายวัน!$M$122:$M$9999,0))),"") | H11: =IFERROR(IF(ISBLANK(INDEX(บันทึกสต็อครายวัน!$H$122:$H$9999,MATCH(TEXT($B$2,"YYYYMMDD")&"|"&$E$2&"|"&B11,บันทึกสต็อครายวัน!$M$122:$M$9999,0))),"",INDEX(บันทึกสต็อครายวัน!$H$122:$H$9999,MATCH(TEXT($B$2,"YYYYMMDD")&"|"&$E$2&"|"&B11,บันทึกสต็อครายวัน!$M$122:$M$9999,0))),"") | I11: =IFERROR(IF(ISBLANK(INDEX(บันทึกสต็อครายวัน!$I$122:$I$9999,MATCH(TEXT($B$2,"YYYYMMDD")&"|"&$E$2&"|"&B11,บันทึกสต็อครายวัน!$M$122:$M$9999,0))),"",INDEX(บันทึกสต็อครายวัน!$I$122:$I$9999,MATCH(TEXT($B$2,"YYYYMMDD")&"|"&$E$2&"|"&B11,บันทึกสต็อครายวัน!$M$122:$M$9999,0))),"") | J11: =IFERROR(IF(ISBLANK(INDEX(บันทึกสต็อครายวัน!$J$122:$J$9999,MATCH(TEXT($B$2,"YYYYMMDD")&"|"&$E$2&"|"&B11,บันทึกสต็อครายวัน!$M$122:$M$9999,0))),"",INDEX(บันทึกสต็อครายวัน!$J$122:$J$9999,MATCH(TEXT($B$2,"YYYYMMDD")&"|"&$E$2&"|"&B11,บันทึกสต็อครายวัน!$M$122:$M$9999,0))),"") | K11: =IFERROR(IF(ISBLANK(INDEX(บันทึกสต็อครายวัน!$K$122:$K$9999,MATCH(TEXT($B$2,"YYYYMMDD")&"|"&$E$2&"|"&B11,บันทึกสต็อครายวัน!$M$122:$M$9999,0))),"",INDEX(บันทึกสต็อครายวัน!$K$122:$K$9999,MATCH(TEXT($B$2,"YYYYMMDD")&"|"&$E$2&"|"&B11,บันทึกสต็อครายวัน!$M$122:$M$9999,0))),"") | L11: =IFERROR(IF(ISBLANK(INDEX(บันทึกสต็อครายวัน!$L$122:$L$9999,MATCH(TEXT($B$2,"YYYYMMDD")&"|"&$E$2&"|"&B11,บันทึกสต็อครายวัน!$M$122:$M$9999,0))),"",INDEX(บันทึกสต็อครายวัน!$L$122:$L$9999,MATCH(TEXT($B$2,"YYYYMMDD")&"|"&$E$2&"|"&B11,บันทึกสต็อครายวัน!$M$122:$M$9999,0))),"")
A12: Yogurt 1kg/Box | B12: Plain Yogurt (ธรรมชาติ) | C12: 1kg/Box | D12: =IFERROR(IF(INDEX(บันทึกสต็อครายวัน!$D$122:$D$9999,MATCH(TEXT($B$2,"YYYYMMDD")&"|"&$E$2&"|"&B12,บันทึกสต็อครายวัน!$M$122:$M$9999,0))="",IFERROR(IF(SUMPRODUCT(MAX((บันทึกสต็อครายวัน!$A$122:$A$9999<$B$2)*(บันทึกสต็อครายวัน!$B$122:$B$9999=$E$2)*(บันทึกสต็อครายวัน!$C$122:$C$9999=B12)*บันทึกสต็อครายวัน!$A$122:$A$9999))=0,"",INDEX(บันทึกสต็อครายวัน!$I$122:$I$9999,MATCH(TEXT(SUMPRODUCT(MAX((บันทึกสต็อครายวัน!$A$122:$A$9999<$B$2)*(บันทึกสต็อครายวัน!$B$122:$B$9999=$E$2)*(บันทึกสต็อครายวัน!$C$122:$C$9999=B12)*บันทึกสต็อครายวัน!$A$122:$A$9999)),"YYYYMMDD")&"|"&$E$2&"|"&B12,บันทึกสต็อครายวัน!$M$122:$M$9999,0))),""),INDEX(บันทึกสต็อครายวัน!$D$122:$D$9999,MATCH(TEXT($B$2,"YYYYMMDD")&"|"&$E$2&"|"&B12,บันทึกสต็อครายวัน!$M$122:$M$9999,0))),IFERROR(IF(SUMPRODUCT(MAX((บันทึกสต็อครายวัน!$A$122:$A$9999<$B$2)*(บันทึกสต็อครายวัน!$B$122:$B$9999=$E$2)*(บันทึกสต็อครายวัน!$C$122:$C$9999=B12)*บันทึกสต็อครายวัน!$A$122:$A$9999))=0,"",INDEX(บันทึกสต็อครายวัน!$I$122:$I$9999,MATCH(TEXT(SUMPRODUCT(MAX((บันทึกสต็อครายวัน!$A$122:$A$9999<$B$2)*(บันทึกสต็อครายวัน!$B$122:$B$9999=$E$2)*(บันทึกสต็อครายวัน!$C$122:$C$9999=B12)*บันทึกสต็อครายวัน!$A$122:$A$9999)),"YYYYMMDD")&"|"&$E$2&"|"&B12,บันทึกสต็อครายวัน!$M$122:$M$9999,0))),"")) -> 4 | E12: =IFERROR(IF(INDEX(บันทึกสต็อครายวัน!$E$122:$E$9999,MATCH(TEXT($B$2,"YYYYMMDD")&"|"&$E$2&"|"&B12,บันทึกสต็อครายวัน!$M$122:$M$9999,0))="",IFERROR(IF(SUMPRODUCT(MAX((บันทึกสต็อครายวัน!$A$122:$A$9999<$B$2)*(บันทึกสต็อครายวัน!$B$122:$B$9999=$E$2)*(บันทึกสต็อครายวัน!$C$122:$C$9999=B12)*บันทึกสต็อครายวัน!$A$122:$A$9999))=0,"",INDEX(บันทึกสต็อครายวัน!$J$122:$J$9999,MATCH(TEXT(SUMPRODUCT(MAX((บันทึกสต็อครายวัน!$A$122:$A$9999<$B$2)*(บันทึกสต็อครายวัน!$B$122:$B$9999=$E$2)*(บันทึกสต็อครายวัน!$C$122:$C$9999=B12)*บันทึกสต็อครายวัน!$A$122:$A$9999)),"YYYYMMDD")&"|"&$E$2&"|"&B12,บันทึกสต็อครายวัน!$M$122:$M$9999,0))),""),INDEX(บันทึกสต็อครายวัน!$E$122:$E$9999,MATCH(TEXT($B$2,"YYYYMMDD")&"|"&$E$2&"|"&B12,บันทึกสต็อครายวัน!$M$122:$M$9999,0))),IFERROR(IF(SUMPRODUCT(MAX((บันทึกสต็อครายวัน!$A$122:$A$9999<$B$2)*(บันทึกสต็อครายวัน!$B$122:$B$9999=$E$2)*(บันทึกสต็อครายวัน!$C$122:$C$9999=B12)*บันทึกสต็อครายวัน!$A$122:$A$9999))=0,"",INDEX(บันทึกสต็อครายวัน!$J$122:$J$9999,MATCH(TEXT(SUMPRODUCT(MAX((บันทึกสต็อครายวัน!$A$122:$A$9999<$B$2)*(บันทึกสต็อครายวัน!$B$122:$B$9999=$E$2)*(บันทึกสต็อครายวัน!$C$122:$C$9999=B12)*บันทึกสต็อครายวัน!$A$122:$A$9999)),"YYYYMMDD")&"|"&$E$2&"|"&B12,บันทึกสต็อครายวัน!$M$122:$M$9999,0))),"")) -> 357 | F12: =IFERROR(IF(ISBLANK(INDEX(บันทึกสต็อครายวัน!$F$122:$F$9999,MATCH(TEXT($B$2,"YYYYMMDD")&"|"&$E$2&"|"&B12,บันทึกสต็อครายวัน!$M$122:$M$9999,0))),"",INDEX(บันทึกสต็อครายวัน!$F$122:$F$9999,MATCH(TEXT($B$2,"YYYYMMDD")&"|"&$E$2&"|"&B12,บันทึกสต็อครายวัน!$M$122:$M$9999,0))),"") | G12: =IFERROR(IF(ISBLANK(INDEX(บันทึกสต็อครายวัน!$G$122:$G$9999,MATCH(TEXT($B$2,"YYYYMMDD")&"|"&$E$2&"|"&B12,บันทึกสต็อครายวัน!$M$122:$M$9999,0))),"",INDEX(บันทึกสต็อครายวัน!$G$122:$G$9999,MATCH(TEXT($B$2,"YYYYMMDD")&"|"&$E$2&"|"&B12,บันทึกสต็อครายวัน!$M$122:$M$9999,0))),"") | H12: =IFERROR(IF(ISBLANK(INDEX(บันทึกสต็อครายวัน!$H$122:$H$9999,MATCH(TEXT($B$2,"YYYYMMDD")&"|"&$E$2&"|"&B12,บันทึกสต็อครายวัน!$M$122:$M$9999,0))),"",INDEX(บันทึกสต็อครายวัน!$H$122:$H$9999,MATCH(TEXT($B$2,"YYYYMMDD")&"|"&$E$2&"|"&B12,บันทึกสต็อครายวัน!$M$122:$M$9999,0))),"") | I12: =IFERROR(IF(ISBLANK(INDEX(บันทึกสต็อครายวัน!$I$122:$I$9999,MATCH(TEXT($B$2,"YYYYMMDD")&"|"&$E$2&"|"&B12,บันทึกสต็อครายวัน!$M$122:$M$9999,0))),"",INDEX(บันทึกสต็อครายวัน!$I$122:$I$9999,MATCH(TEXT($B$2,"YYYYMMDD")&"|"&$E$2&"|"&B12,บันทึกสต็อครายวัน!$M$122:$M$9999,0))),"") | J12: =IFERROR(IF(ISBLANK(INDEX(บันทึกสต็อครายวัน!$J$122:$J$9999,MATCH(TEXT($B$2,"YYYYMMDD")&"|"&$E$2&"|"&B12,บันทึกสต็อครายวัน!$M$122:$M$9999,0))),"",INDEX(บันทึกสต็อครายวัน!$J$122:$J$9999,MATCH(TEXT($B$2,"YYYYMMDD")&"|"&$E$2&"|"&B12,บันทึกสต็อครายวัน!$M$122:$M$9999,0))),"") | K12: =IFERROR(IF(ISBLANK(INDEX(บันทึกสต็อครายวัน!$K$122:$K$9999,MATCH(TEXT($B$2,"YYYYMMDD")&"|"&$E$2&"|"&B12,บันทึกสต็อครายวัน!$M$122:$M$9999,0))),"",INDEX(บันทึกสต็อครายวัน!$K$122:$K$9999,MATCH(TEXT($B$2,"YYYYMMDD")&"|"&$E$2&"|"&B12,บันทึกสต็อครายวัน!$M$122:$M$9999,0))),"") | L12: =IFERROR(IF(ISBLANK(INDEX(บันทึกสต็อครายวัน!$L$122:$L$9999,MATCH(TEXT($B$2,"YYYYMMDD")&"|"&$E$2&"|"&B12,บันทึกสต็อครายวัน!$M$122:$M$9999,0))),"",INDEX(บันทึกสต็อครายวัน!$L$122:$L$9999,MATCH(TEXT($B$2,"YYYYMMDD")&"|"&$E$2&"|"&B12,บันทึกสต็อครายวัน!$M$122:$M$9999,0))),"")
A13: Yogurt 500g/Box | B13: Greek Yogurt 500g | C13: 500g/Box | D13: =IFERROR(IF(INDEX(บันทึกสต็อครายวัน!$D$122:$D$9999,MATCH(TEXT($B$2,"YYYYMMDD")&"|"&$E$2&"|"&B13,บันทึกสต็อครายวัน!$M$122:$M$9999,0))="",IFERROR(IF(SUMPRODUCT(MAX((บันทึกสต็อครายวัน!$A$122:$A$9999<$B$2)*(บันทึกสต็อครายวัน!$B$122:$B$9999=$E$2)*(บันทึกสต็อครายวัน!$C$122:$C$9999=B13)*บันทึกสต็อครายวัน!$A$122:$A$9999))=0,"",INDEX(บันทึกสต็อครายวัน!$I$122:$I$9999,MATCH(TEXT(SUMPRODUCT(MAX((บันทึกสต็อครายวัน!$A$122:$A$9999<$B$2)*(บันทึกสต็อครายวัน!$B$122:$B$9999=$E$2)*(บันทึกสต็อครายวัน!$C$122:$C$9999=B13)*บันทึกสต็อครายวัน!$A$122:$A$9999)),"YYYYMMDD")&"|"&$E$2&"|"&B13,บันทึกสต็อครายวัน!$M$122:$M$9999,0))),""),INDEX(บันทึกสต็อครายวัน!$D$122:$D$9999,MATCH(TEXT($B$2,"YYYYMMDD")&"|"&$E$2&"|"&B13,บันทึกสต็อครายวัน!$M$122:$M$9999,0))),IFERROR(IF(SUMPRODUCT(MAX((บันทึกสต็อครายวัน!$A$122:$A$9999<$B$2)*(บันทึกสต็อครายวัน!$B$122:$B$9999=$E$2)*(บันทึกสต็อครายวัน!$C$122:$C$9999=B13)*บันทึกสต็อครายวัน!$A$122:$A$9999))=0,"",INDEX(บันทึกสต็อครายวัน!$I$122:$I$9999,MATCH(TEXT(SUMPRODUCT(MAX((บันทึกสต็อครายวัน!$A$122:$A$9999<$B$2)*(บันทึกสต็อครายวัน!$B$122:$B$9999=$E$2)*(บันทึกสต็อครายวัน!$C$122:$C$9999=B13)*บันทึกสต็อครายวัน!$A$122:$A$9999)),"YYYYMMDD")&"|"&$E$2&"|"&B13,บันทึกสต็อครายวัน!$M$122:$M$9999,0))),"")) -> 6 | E13: =IFERROR(IF(INDEX(บันทึกสต็อครายวัน!$E$122:$E$9999,MATCH(TEXT($B$2,"YYYYMMDD")&"|"&$E$2&"|"&B13,บันทึกสต็อครายวัน!$M$122:$M$9999,0))="",IFERROR(IF(SUMPRODUCT(MAX((บันทึกสต็อครายวัน!$A$122:$A$9999<$B$2)*(บันทึกสต็อครายวัน!$B$122:$B$9999=$E$2)*(บันทึกสต็อครายวัน!$C$122:$C$9999=B13)*บันทึกสต็อครายวัน!$A$122:$A$9999))=0,"",INDEX(บันทึกสต็อครายวัน!$J$122:$J$9999,MATCH(TEXT(SUMPRODUCT(MAX((บันทึกสต็อครายวัน!$A$122:$A$9999<$B$2)*(บันทึกสต็อครายวัน!$B$122:$B$9999=$E$2)*(บันทึกสต็อครายวัน!$C$122:$C$9999=B13)*บันทึกสต็อครายวัน!$A$122:$A$9999)),"YYYYMMDD")&"|"&$E$2&"|"&B13,บันทึกสต็อครายวัน!$M$122:$M$9999,0))),""),INDEX(บันทึกสต็อครายวัน!$E$122:$E$9999,MATCH(TEXT($B$2,"YYYYMMDD")&"|"&$E$2&"|"&B13,บันทึกสต็อครายวัน!$M$122:$M$9999,0))),IFERROR(IF(SUMPRODUCT(MAX((บันทึกสต็อครายวัน!$A$122:$A$9999<$B$2)*(บันทึกสต็อครายวัน!$B$122:$B$9999=$E$2)*(บันทึกสต็อครายวัน!$C$122:$C$9999=B13)*บันทึกสต็อครายวัน!$A$122:$A$9999))=0,"",INDEX(บันทึกสต็อครายวัน!$J$122:$J$9999,MATCH(TEXT(SUMPRODUCT(MAX((บันทึกสต็อครายวัน!$A$122:$A$9999<$B$2)*(บันทึกสต็อครายวัน!$B$122:$B$9999=$E$2)*(บันทึกสต็อครายวัน!$C$122:$C$9999=B13)*บันทึกสต็อครายวัน!$A$122:$A$9999)),"YYYYMMDD")&"|"&$E$2&"|"&B13,บันทึกสต็อครายวัน!$M$122:$M$9999,0))),"")) -> 0 | F13: =IFERROR(IF(ISBLANK(INDEX(บันทึกสต็อครายวัน!$F$122:$F$9999,MATCH(TEXT($B$2,"YYYYMMDD")&"|"&$E$2&"|"&B13,บันทึกสต็อครายวัน!$M$122:$M$9999,0))),"",INDEX(บันทึกสต็อครายวัน!$F$122:$F$9999,MATCH(TEXT($B$2,"YYYYMMDD")&"|"&$E$2&"|"&B13,บันทึกสต็อครายวัน!$M$122:$M$9999,0))),"") | G13: =IFERROR(IF(ISBLANK(INDEX(บันทึกสต็อครายวัน!$G$122:$G$9999,MATCH(TEXT($B$2,"YYYYMMDD")&"|"&$E$2&"|"&B13,บันทึกสต็อครายวัน!$M$122:$M$9999,0))),"",INDEX(บันทึกสต็อครายวัน!$G$122:$G$9999,MATCH(TEXT($B$2,"YYYYMMDD")&"|"&$E$2&"|"&B13,บันทึกสต็อครายวัน!$M$122:$M$9999,0))),"") | H13: =IFERROR(IF(ISBLANK(INDEX(บันทึกสต็อครายวัน!$H$122:$H$9999,MATCH(TEXT($B$2,"YYYYMMDD")&"|"&$E$2&"|"&B13,บันทึกสต็อครายวัน!$M$122:$M$9999,0))),"",INDEX(บันทึกสต็อครายวัน!$H$122:$H$9999,MATCH(TEXT($B$2,"YYYYMMDD")&"|"&$E$2&"|"&B13,บันทึกสต็อครายวัน!$M$122:$M$9999,0))),"") | I13: =IFERROR(IF(ISBLANK(INDEX(บันทึกสต็อครายวัน!$I$122:$I$9999,MATCH(TEXT($B$2,"YYYYMMDD")&"|"&$E$2&"|"&B13,บันทึกสต็อครายวัน!$M$122:$M$9999,0))),"",INDEX(บันทึกสต็อครายวัน!$I$122:$I$9999,MATCH(TEXT($B$2,"YYYYMMDD")&"|"&$E$2&"|"&B13,บันทึกสต็อครายวัน!$M$122:$M$9999,0))),"") | J13: =IFERROR(IF(ISBLANK(INDEX(บันทึกสต็อครายวัน!$J$122:$J$9999,MATCH(TEXT($B$2,"YYYYMMDD")&"|"&$E$2&"|"&B13,บันทึกสต็อครายวัน!$M$122:$M$9999,0))),"",INDEX(บันทึกสต็อครายวัน!$J$122:$J$9999,MATCH(TEXT($B$2,"YYYYMMDD")&"|"&$E$2&"|"&B13,บันทึกสต็อครายวัน!$M$122:$M$9999,0))),"") | K13: =IFERROR(IF(ISBLANK(INDEX(บันทึกสต็อครายวัน!$K$122:$K$9999,MATCH(TEXT($B$2,"YYYYMMDD")&"|"&$E$2&"|"&B13,บันทึกสต็อครายวัน!$M$122:$M$9999,0))),"",INDEX(บันทึกสต็อครายวัน!$K$122:$K$9999,MATCH(TEXT($B$2,"YYYYMMDD")&"|"&$E$2&"|"&B13,บันทึกสต็อครายวัน!$M$122:$M$9999,0))),"") | L13: =IFERROR(IF(ISBLANK(INDEX(บันทึกสต็อครายวัน!$L$122:$L$9999,MATCH(TEXT($B$2,"YYYYMMDD")&"|"&$E$2&"|"&B13,บันทึกสต็อครายวัน!$M$122:$M$9999,0))),"",INDEX(บันทึกสต็อครายวัน!$L$122:$L$9999,MATCH(TEXT($B$2,"YYYYMMDD")&"|"&$E$2&"|"&B13,บันทึกสต็อครายวัน!$M$122:$M$9999,0))),"")
A14: Yogurt 500g/Box | B14: Plain Yogurt 500g | C14: 500g/Box | D14: =IFERROR(IF(INDEX(บันทึกสต็อครายวัน!$D$122:$D$9999,MATCH(TEXT($B$2,"YYYYMMDD")&"|"&$E$2&"|"&B14,บันทึกสต็อครายวัน!$M$122:$M$9999,0))="",IFERROR(IF(SUMPRODUCT(MAX((บันทึกสต็อครายวัน!$A$122:$A$9999<$B$2)*(บันทึกสต็อครายวัน!$B$122:$B$9999=$E$2)*(บันทึกสต็อครายวัน!$C$122:$C$9999=B14)*บันทึกสต็อครายวัน!$A$122:$A$9999))=0,"",INDEX(บันทึกสต็อครายวัน!$I$122:$I$9999,MATCH(TEXT(SUMPRODUCT(MAX((บันทึกสต็อครายวัน!$A$122:$A$9999<$B$2)*(บันทึกสต็อครายวัน!$B$122:$B$9999=$E$2)*(บันทึกสต็อครายวัน!$C$122:$C$9999=B14)*บันทึกสต็อครายวัน!$A$122:$A$9999)),"YYYYMMDD")&"|"&$E$2&"|"&B14,บันทึกสต็อครายวัน!$M$122:$M$9999,0))),""),INDEX(บันทึกสต็อครายวัน!$D$122:$D$9999,MATCH(TEXT($B$2,"YYYYMMDD")&"|"&$E$2&"|"&B14,บันทึกสต็อครายวัน!$M$122:$M$9999,0))),IFERROR(IF(SUMPRODUCT(MAX((บันทึกสต็อครายวัน!$A$122:$A$9999<$B$2)*(บันทึกสต็อครายวัน!$B$122:$B$9999=$E$2)*(บันทึกสต็อครายวัน!$C$122:$C$9999=B14)*บันทึกสต็อครายวัน!$A$122:$A$9999))=0,"",INDEX(บันทึกสต็อครายวัน!$I$122:$I$9999,MATCH(TEXT(SUMPRODUCT(MAX((บันทึกสต็อครายวัน!$A$122:$A$9999<$B$2)*(บันทึกสต็อครายวัน!$B$122:$B$9999=$E$2)*(บันทึกสต็อครายวัน!$C$122:$C$9999=B14)*บันทึกสต็อครายวัน!$A$122:$A$9999)),"YYYYMMDD")&"|"&$E$2&"|"&B14,บันทึกสต็อครายวัน!$M$122:$M$9999,0))),"")) -> 2 | E14: =IFERROR(IF(INDEX(บันทึกสต็อครายวัน!$E$122:$E$9999,MATCH(TEXT($B$2,"YYYYMMDD")&"|"&$E$2&"|"&B14,บันทึกสต็อครายวัน!$M$122:$M$9999,0))="",IFERROR(IF(SUMPRODUCT(MAX((บันทึกสต็อครายวัน!$A$122:$A$9999<$B$2)*(บันทึกสต็อครายวัน!$B$122:$B$9999=$E$2)*(บันทึกสต็อครายวัน!$C$122:$C$9999=B14)*บันทึกสต็อครายวัน!$A$122:$A$9999))=0,"",INDEX(บันทึกสต็อครายวัน!$J$122:$J$9999,MATCH(TEXT(SUMPRODUCT(MAX((บันทึกสต็อครายวัน!$A$122:$A$9999<$B$2)*(บันทึกสต็อครายวัน!$B$122:$B$9999=$E$2)*(บันทึกสต็อครายวัน!$C$122:$C$9999=B14)*บันทึกสต็อครายวัน!$A$122:$A$9999)),"YYYYMMDD")&"|"&$E$2&"|"&B14,บันทึกสต็อครายวัน!$M$122:$M$9999,0))),""),INDEX(บันทึกสต็อครายวัน!$E$122:$E$9999,MATCH(TEXT($B$2,"YYYYMMDD")&"|"&$E$2&"|"&B14,บันทึกสต็อครายวัน!$M$122:$M$9999,0))),IFERROR(IF(SUMPRODUCT(MAX((บันทึกสต็อครายวัน!$A$122:$A$9999<$B$2)*(บันทึกสต็อครายวัน!$B$122:$B$9999=$E$2)*(บันทึกสต็อครายวัน!$C$122:$C$9999=B14)*บันทึกสต็อครายวัน!$A$122:$A$9999))=0,"",INDEX(บันทึกสต็อครายวัน!$J$122:$J$9999,MATCH(TEXT(SUMPRODUCT(MAX((บันทึกสต็อครายวัน!$A$122:$A$9999<$B$2)*(บันทึกสต็อครายวัน!$B$122:$B$9999=$E$2)*(บันทึกสต็อครายวัน!$C$122:$C$9999=B14)*บันทึกสต็อครายวัน!$A$122:$A$9999)),"YYYYMMDD")&"|"&$E$2&"|"&B14,บันทึกสต็อครายวัน!$M$122:$M$9999,0))),"")) -> 0 | F14: =IFERROR(IF(ISBLANK(INDEX(บันทึกสต็อครายวัน!$F$122:$F$9999,MATCH(TEXT($B$2,"YYYYMMDD")&"|"&$E$2&"|"&B14,บันทึกสต็อครายวัน!$M$122:$M$9999,0))),"",INDEX(บันทึกสต็อครายวัน!$F$122:$F$9999,MATCH(TEXT($B$2,"YYYYMMDD")&"|"&$E$2&"|"&B14,บันทึกสต็อครายวัน!$M$122:$M$9999,0))),"") | G14: =IFERROR(IF(ISBLANK(INDEX(บันทึกสต็อครายวัน!$G$122:$G$9999,MATCH(TEXT($B$2,"YYYYMMDD")&"|"&$E$2&"|"&B14,บันทึกสต็อครายวัน!$M$122:$M$9999,0))),"",INDEX(บันทึกสต็อครายวัน!$G$122:$G$9999,MATCH(TEXT($B$2,"YYYYMMDD")&"|"&$E$2&"|"&B14,บันทึกสต็อครายวัน!$M$122:$M$9999,0))),"") | H14: =IFERROR(IF(ISBLANK(INDEX(บันทึกสต็อครายวัน!$H$122:$H$9999,MATCH(TEXT($B$2,"YYYYMMDD")&"|"&$E$2&"|"&B14,บันทึกสต็อครายวัน!$M$122:$M$9999,0))),"",INDEX(บันทึกสต็อครายวัน!$H$122:$H$9999,MATCH(TEXT($B$2,"YYYYMMDD")&"|"&$E$2&"|"&B14,บันทึกสต็อครายวัน!$M$122:$M$9999,0))),"") | I14: =IFERROR(IF(ISBLANK(INDEX(บันทึกสต็อครายวัน!$I$122:$I$9999,MATCH(TEXT($B$2,"YYYYMMDD")&"|"&$E$2&"|"&B14,บันทึกสต็อครายวัน!$M$122:$M$9999,0))),"",INDEX(บันทึกสต็อครายวัน!$I$122:$I$9999,MATCH(TEXT($B$2,"YYYYMMDD")&"|"&$E$2&"|"&B14,บันทึกสต็อครายวัน!$M$122:$M$9999,0))),"") | J14: =IFERROR(IF(ISBLANK(INDEX(บันทึกสต็อครายวัน!$J$122:$J$9999,MATCH(TEXT($B$2,"YYYYMMDD")&"|"&$E$2&"|"&B14,บันทึกสต็อครายวัน!$M$122:$M$9999,0))),"",INDEX(บันทึกสต็อครายวัน!$J$122:$J$9999,MATCH(TEXT($B$2,"YYYYMMDD")&"|"&$E$2&"|"&B14,บันทึกสต็อครายวัน!$M$122:$M$9999,0))),"") | K14: =IFERROR(IF(ISBLANK(INDEX(บันทึกสต็อครายวัน!$K$122:$K$9999,MATCH(TEXT($B$2,"YYYYMMDD")&"|"&$E$2&"|"&B14,บันทึกสต็อครายวัน!$M$122:$M$9999,0))),"",INDEX(บันทึกสต็อครายวัน!$K$122:$K$9999,MATCH(TEXT($B$2,"YYYYMMDD")&"|"&$E$2&"|"&B14,บันทึกสต็อครายวัน!$M$122:$M$9999,0))),"") | L14: =IFERROR(IF(ISBLANK(INDEX(บันทึกสต็อครายวัน!$L$122:$L$9999,MATCH(TEXT($B$2,"YYYYMMDD")&"|"&$E$2&"|"&B14,บันทึกสต็อครายวัน!$M$122:$M$9999,0))),"",INDEX(บันทึกสต็อครายวัน!$L$122:$L$9999,MATCH(TEXT($B$2,"YYYYMMDD")&"|"&$E$2&"|"&B14,บันทึกสต็อครายวัน!$M$122:$M$9999,0))),"")
